Workbook

Sheet Total
B1: YEAR 2026
A2: TOTAL BUDGET | B2: 3087000 | C2: =B2/4 -> 771750 | E2: LAC SESSION SCHEDULE: | H2: Seminar Registration | L2: TRAVELS | M2: Tarpauling printing
E3: FEB 2024 | F3: 10000 | H3: 45352 | J3: =MARCH!H14 -> 4000 | K3: MAR | L3: 4000 | M3: IECA
A4: JANUARY | B4: =January!I24 -> 148600 | E4: APRIL 2024 | F4: 10000 | H4: May | J4: =May!G14 -> 30000 | K4: May | L4: =May!G15 -> 30000 | M4: AP
A5: FEBRUARY | B5: =February!H63 -> 722950 | E5: SEPT. 2024 | F5: 10000 | H5: 45101 | J5: =June!G14 -> 25000 | K5: JUNE | L5: =June!G15 -> 25000 | M5: Career Guidance
A6: MARCH | B6: =MARCH!H48 -> 451458 | C6: =SUM(B4:B6) -> 1323008 | D6: =C6-C2 -> 551258 | E6: NOV. 2024 | F6: 10000 | H6: AUGUST | J6: =August!G14 -> 10000 | K6: AUG | L6: =August!G15 -> 15000 | M6: Science Camp
A7: APRIL | B7: =April!G37 -> 386800 | E7: TOTAL | F7: =SUM(F3:F6) -> 40000 | H7: SEPT | J7: =September!G14 -> 20000 | K7: SEPT | L7: =September!G15 -> 5000 | M7: IECA
A8: MAY | B8: =May!G43 -> 546320 | H8: November | J8: =November!G14 -> 30000 | K8: Nov | L8: =November!G15 -> 30000 | M8: IECA
A9: JUNE | B9: =June!G40 -> 350800 | C9: =SUM(B7:B9) -> 1283920 | D9: =C9-C2 -> 512170 | J9: =SUM(J3:J8) -> 119000 | L9: =SUM(L3:L8) -> 109000 | M9: IECA
A10: JULY | B10: =July!G53 -> 513600 | M10: BE
A11: AUGUST | B11: =August!G43 -> 415600 | E11: INSET SCHEDULE: | L11: 4
A12: SEPTEMBER | B12: =September!G37 -> 369600 | C12: =SUM(B10:B12) -> 1298800 | D12: =C12-C2 -> 527050 | E12: OCTOBER
A13: OCTOBER | B13: =October!G57 -> 804300 | F13: 165000 | H13: ICT Repair
A14: NOVEMBER | B14: =November!G35 -> 310100 | H14: June | I14: 15000
A15: DECEMBER | B15: =December!G25 -> 184100 | C15: =SUM(B13:B15) -> 1298500 | D15: =C15-C2 -> 526750 | H15: Oct. | I15: 10000
A16: TOTAL | B16: =SUM(B4:B15) -> 5204228 | E16: ELECTRICITY:
B17: =B2-B16 -> -2117228 | E17: JAN | F17: =January!I9 -> 30000
E18: FEB | F18: =February!H9 -> 40000
E19: MARCH | F19: =MARCH!H9 -> 40000
E20: APRIL | F20: =April!G10 -> 40000
E21: MAY | F21: =May!G10 -> 30000 | M21: janitorial
E22: JUNE | F22: =June!G10 -> 30000
E23: JULY | F23: =July!G10 -> 40000 | M23: total
E24: AUGUST | F24: =August!G10 -> 40000
E25: SEPTEMBER | F25: =September!G10 -> 40000
E26: OCTOBER | F26: =October!G10 -> 40000
E27: NOVEMBER | F27: =November!G10 -> 40000
E28: DECEMBER | F28: =December!G8 -> 40000
E29: TOTAL | F29: =SUM(F17:F28) -> 450000
E31: REPAIR AND MAINTENANCE:
A32: Janitorial 2024 | E32: R&m - School Building | F32: 135500
A33: march | B33: =April!G25 -> 40000 | E33: R&M-Furniture and Fixtures | F33: 30000
A34: AUGUST | E34: R&M-Other Structures | F34: 55000 | J34: 4000 | K34: GAD-CR | L34: 15000
B35: =SUM(B33:B34) -> 40000 | C35: =B35+[1]Total!$B$44 -> 70000 | E35: R&M - Motor Vehicle | F35: 50000
E36: R&M - Office equipment | F36: 10000
A37: Repair water system | E37: R&M-ICT Equipment | J37: Actual Disbursement | K37: 1652749.6
A38: march | B38: =February!H56 -> 20000 | E38: R&M- Printing Equipment | F38: 40000 | J38: TOTAL ALLOTMENT | K38: 2815000
A39: june | B39: =May!G31 -> 10000 | E39: R&M-Water Supplies Systems | F39: 18000 | J39: APPLICABLE TO JUL TO DEC | K39: 1162250.4
B40: =SUM(B38:B39) -> 30000 | C40: =B40+5100+15000 -> 50100 | E40: R&M-Other Machinery and Equipment | F40: 5000 | J40: Remaining allotment | K40: 1162250.4
E41: TOTAL | F41: =SUM(F32:F40) -> 343500 | G41: =(F41/B16) -> 0.066004026
...

Sheet January
A1: LUIS HERVIAS NATIONAL HIGH SCHOOL - JUNIOR HIGH SCHOOL
A3: PROGRAMS/ PROJECTS/ ACTIVITIES, CY 2026
C4: JANUARY 2026
A6: Key Result Area based on OPCRF | B6: Specific Program (SIP) | C6: Programs/Projects/Activities | E6: Purpose / Objectives | F6: Performance Indicator | G6: Resources Needed | I6: Estimated Cost | J6: Account Title | K6: Account Code
G7: Description | H7: Quantity
C8: Regular Expenditure
A9: KRA 1: LEADING STRATEGICALLY | B9: Overhead | C9: Pay monthly electricity bill | E9: Paid electricity of the JHS to ensure continuous provision of electrical supply | F9: # of monthly electricty bills | G9: electrical supply | H9: 1 | I9: 30000 | J9: Electricity Expenses | K9: 5020402000
A10: KRA 1: LEADING STRATEGICALLY | B10: Overhead | C10: Pay monthly landline subscription | E10: Paid landline subscription for teachers and staff with official transactions | F10: # of monthly landline services paid | G10: telephone services | H10: 1 | I10: 2000 | J10: Communication Expenses Landline | K10: 5020202002
A11: KRA 1: LEADING STRATEGICALLY | B11: Overhead | C11: Pay monthly internet subscription | E11: Paid monthly internet connection for academic & administrative use for school learners support services | F11: # of monthly internet services paid | G11: Fiber internet | H11: 1 | I11: 2100 | J11: Communication Expenses Internet Subscription | K11: 5020503000
A12: KRA 1: LEADING STRATEGICALLY | B12: Overhead | C12: Procure fuel for school sevice in submission of school report | E12: Provided transportation for teachers and staff in submission of school report | F12: # of procured fuel for school service | G12: Gasoline | H12: 4 | I12: 5000 | J12: Fuel, Oil, and Lubricants | K12: 5020309000
A13: KRA 1: LEADING STRATEGICALLY | B13: Overhead | C13: Pay hired Job Order Utility Personnel | E13: Paid hired job order utility services | F13: # of personnel paid | G13: wages | H13: 2 | I13: 22500 | J13: Other General Services | K13: 50212990000
A14: KRA 2- MANAGING SCHOOL OPERATIONS AND RESOURCES | C14: Pay monthly internet bills | E14: Paid monthly internet connection for academic & administrative use | F14: # of internet bills paid | G14: 5Mbps Internet Connection | H14: 3 | I14: 5000 | J14: Internet Subscription Expenses | K14: 5020503000
A15: KRA 2- MANAGING SCHOOL OPERATIONS AND RESOURCES | C15: Pay electricity bill | E15: Paid monthly electricity bill for the School facilities | F15: # of electricity bills paid | G15: Electricity | H15: 1 | I15: 70000 | J15: Electricity Expenses | K15: 5020402000
A16: Subtotal | I16: =SUM(I9:I15) -> 136600
C17: Project Related Expenditure
A19: KRA 2- MANAGING SCHOOL OPERATIONS AND RESOURCES | C19: Pay Student Accident Insurance of Grade 12 students | E19: Paid Student Accident Insurance for Grade 12 Immersees | F19: # of paid student accident insurance | G19: Student Accident Insurance | H19: 1 | I19: 12000 | J19: Insurance Expenses | K19: 5021503000
A20: Subtotal | I20: =I19 -> 12000
C21: Repair and Maintenance
A22: Subtotal
C23: NONE
A24: Total budget for the Month of January 2026 | I24: =I16+I20 -> 148600

Sheet February
A1: LUIS HERVIAS NATIONAL HIGH SCHOOL - JUNIOR HIGH SCHOOL
A3: PROGRAMS/ PROJECTS/ ACTIVITIES, CY 2026
C4: FEBRUARY 2026
A6: Key Result Area based on OPCRF | B6: Specific Program (SIP) | C6: Programs/Projects/Activities | D6: Purpose / Objectives | E6: Performance Indicator | F6: Resources Needed | H6: Estimated Cost | I6: Account Title | J6: Account Code
F7: Description | G7: Quantity
C8: Regular Expenditure
A9: KRA 1: LEADING STRATEGICALLY | B9: Overhead | C9: Pay monthly electricity bill | D9: Paid electricity of the JHS to ensure continuous provision of electrical supply | E9: # of monthly electricty bills | F9: electrical supply | G9: 1 | H9: 40000 | I9: Electricity Expenses | J9: 5020402000
A10: KRA 1: LEADING STRATEGICALLY | B10: Overhead | C10: Pay monthly landline subscription | D10: Paid landline subscription for teachers and staff with official transactions | E10: # of monthly landline services paid | F10: telephone services | G10: 1 | H10: 2000 | I10: Communication Expenses Landline | J10: 5020202002
A11: KRA 1: LEADING STRATEGICALLY | B11: Overhead | C11: Pay monthly internet subscription | D11: Paid monthly internet connection for academic & administrative use for school learners support services | E11: # of monthly internet services paid | F11: Fiber internet | G11: 1 | H11: 2100 | I11: Communication Expenses Internet Subscription | J11: 5020503000
A12: KRA 1: LEADING STRATEGICALLY | B12: Overhead | C12: Procure fuel for school service in submission of school report | D12: Provided transportation for teachers and staff in submission of school report | E12: # of procured fuel for school service | F12: Gasoline | G12: 4 | H12: 5000 | I12: Fuel, Oil, and Lubricants | J12: 5020309000
A13: KRA 1: LEADING STRATEGICALLY | B13: Overhead | C13: Procure Purified Drinking Water in compliance to SBM Wins Programs | D13: Procured gallons of purifieddrinking water to students and personnel | E13: # of procured drinking water | F13: Drinking Water | G13: 1 | H13: 3000 | I13: Other Supplies and Material Expenses | J13: 5020399000
A14: KRA 1: LEADING STRATEGICALLY | B14: Overhead | C14: Pay hired Job Order Utility Personnel | D14: Paid hired job order utility services | E14: # of personnel paid | F14: wages | G14: 2 | H14: 22500 | I14: Other General Services | J14: 50212990000
A16: KRA 2- MANAGING SCHOOL OPERATIONS AND RESOURCES | B16: Overhead | C16: Pay monthly internet bills | D16: Paid monthly internet connection for academic & administrative use | E16: # of internet bills paid | F16: 5Mbps Internet Connection | G16: 3 | H16: 5000 | I16: Internet Subscription Expenses | J16: 5020503000
A17: KRA 2- MANAGING SCHOOL OPERATIONS AND RESOURCES | B17: Overhead | C17: Pay electricity bill | D17: Paid monthly electricity bill for the School facilities | E17: # of electricity bills paid | F17: Electricity | G17: 1 | H17: 100000 | I17: Electricity Expenses | J17: 5020402000
C18: SUB-TOTAL | H18: =SUM(H9:H17) -> 179600
C19: Project Related Expenditure
A20: KRA 3: FOCUSING ON TEACHING AND LEARNING | B20: Empowering teachers through trainings and seminars | C20: Train School based teaching and non-teaching personnel of LHNHS thru the conduct of LAC Session | D20: Trained School based teaching and non-teaching personnel of LHNHS thru the conduct of LAC Session for learning and development | E20: # of procured snacks | F20: Snacks | G20: 1 | H20: 10000 | I20: Training Expenses | J20: 5020201002
A21: KRA 3: FOCUSING ON TEACHING AND LEARNING | B21: PLACE- Provision for Learners and Curriculum Enhancers | C21: Procure television for teachers interactive lesson | D21: Procured television for teachers interactive lesson | E21: # of procured Television | F21: (please see annexes of list of television) | G21: 3 | H21: 63000 | I21: Semi-Expendable - ICT Equipment | J21: 5020321003
A22: KRA 1: LEADING STRATEGICALLY | C22: Procure of Tools, Materials and ICT Equipment for TLE Offerings | D22: Procured tools and materials for Cookery, Hair dressing, EPAS, Needlecraft and ICT equipment for Tour Guiding to enhance students skills | E22: # of procured portable sewing machine | F22: (please see annexes for the list of sewing machine) | G22: 1 | H22: 5000 | I22: Other Machinery and Equipment | J22: 5020321099
B23: “Pa Bonggahan ng Talento sa Teknolohiya” | E23: # of procured ICT Equipment -speaker | F23: (please see annexes for the list of tools and materials) | G23: 1 | H23: 11000 | I23: Semi-Expendable - ICT Equipment | J23: 5020321003
E24: # of procured EPAS equipment | F24: (please see annexes for the list of tools and materials) | G24: 1 | H24: 23500 | I24: Other Machinery and Equipment | J24: 5020321099
E25: # of procured equipment and materials for Hairdressing offering | F25: (please see annexes for the list materials) | G25: 1 | H25: 8500 | I25: Other Supplies and Material Expenses | J25: 5020399000
F26: (please see annexes for the list of equipment) | G26: 1 | H26: 12000 | I26: Other Machinery and Equipment | J26: 5020321099
E27: # of procured equipment and materials for Cookery offering | F27: (please see annexes for the list materials) | G27: 1 | H27: 18000 | I27: Other Supplies and Material Expenses | J27: 5020399000
F28: (please see annexes for the list of equipment) | G28: 1 | H28: 12000 | I28: Other Machinery and Equipment | J28: 5020321099
A29: KRA 3: FOCUSING ON TEACHING AND LEARNING | B29: Empowering HS Students with career guidance | C29: Provide Career Guidance training | D29: Provided of Career Guidance training for Grade 10 students | E29: # of procured office supplies | F29: (please see annexes for the list of office supplies) | G29: 1 | H29: 4000 | I29: Office Supplies Expenses | J29: 5020301003
E30: # of printed tarpaulin | F30: Tarpaulin | G30: 1 | H30: 1000 | I30: Printing and Publication Expenses | J30: 5029902000
A31: KRA 1: LEADING STRATEGICALLY | B31: Sports Enhancement Program | C31: Procure of Sports Equipment | D31: Procured sports equipment for Arnis, Badminton, Basketball 3x3, Futsal and Volleyball to improve students skills in different sports. | E31: # of procured sports equipment | F31: (please see annexes for the list of sports equipment) | G31: 1 | H31: 90000 | I31: Semi Expendable-Sports Equipment | J31: 5020321012
A32: KRA 1: LEADING STRATEGICALLY | B32: SDRRMO TEA (Tools and Equipment) | C32: Procure additional equipment for SDRRM Program | E32: # of procured SDRRM equipment | F32: (please see annexes for list of SDRRM equipment) | G32: 1 | H32: 20000 | I32: Disaster Response and Rescue Equipment | J32: 5021321008
A33: KRA 2- MANAGING SCHOOL OPERATIONS AND RESOURCES | C33: Procure Expendable materials & ICT Equipment for CSS SHS students | D33: Procured materials and ICT Equipment to improve the ICT related skills of CSS SHS students | E33: # of procurement made | G33: 1 | H33: 20750 | I33: Semi Expendable - ICT Equipment | J33: 5020321003
A36: KRA 2 - MANAGING SCHOOL OPERATIONS AND RESOURCES | C36: Procure Semi Expendable - ICT Equipment for conferences and storage | D36: Procured ICT Equipment for ICT Laboratory conferences and storage | E36: # of procurement made | G36: 1 | H36: 33000 | I36: Semi Expendable - ICT Equipment | J36: 5020321003
A44: KRA 2- MANAGING SCHOOL OPERATIONS AND RESOURCES | C44: Procure Expendable materials and Equipment for DRESSMAKING | D44: Procured Expendable materials and Equipment for DRESSMAKING | E44: # of procurement made | G44: 1 | H44: 20000 | I44: Semi Expendable - Furnitures and Fixtures Expense | J44: 5020322001
I45: Semi Expendable - Other Machinery & Equipment | J45: 5020321099
I47: Other Supplies & Materials | J47: 5020399000
A49: KRA 2 - MANAGING SCHOOL OPERATIONS AND RESOURCES | C49: Procure Materials for SHS Career Guidance | D49: Procured tarpaulin and planners as token for Career Guidance | E49: No. of procurement made | G49: 1 | H49: 5000 | I49: Office Supplies Expenses | J49: 5020301002
A52: KRA 1 - LEADING STRATEGICALLY | C52: Pay maintenance services for online SF9 system | D52: Paid maintenance services for online SF9 system | E52: # of services maintained | F52: maintenance fee | G52: 1 | H52: 6000 | I52: Other Professional Services | J52: 5021199000
C53: SUB-TOTAL | H53: =SUM(H20:H52) -> 362750
C54: Repair and Maintenance
A55: KRA 1: LEADING STRATEGICALLY | B55: Overhead | C55: Provision Materials and Labor for Repair and Maintenance of School Vehicle | D55: Provided materials and labor for repair and maintenance of school vehicle for submission of school reports | E55: # of repaired vehicle | F55: Vehicle | G55: 1 | H55: 10000 | I55: Repair and Maintenance - Motor Vehicle | J55: 5021306001
A56: KRA 1: LEADING STRATEGICALLY | B56: Overhead | C56: Procure labor and materials for Repair and Maintenance of Water Supply System | D56: Procured labor and materials for broken electric water pump | E56: # of water pump repaired | F56: (please see annexes for the list of repair materials) | G56: 1 | H56: 20000 | I56: Repair and Maintenance - Water Supplies System | J56: 5021303004
...

Sheet MARCH
A1: LUIS HERVIAS NATIONAL HIGH SCHOOL - JUNIOR HIGH SCHOOL
A3: PROGRAMS/ PROJECTS/ ACTIVITIES, CY 2026
C4: MARCH 2026
A6: Key Result Area based on OPCRF | B6: Specific Program (SIP) | C6: Programs/Projects/Activities | D6: Purpose / Objectives | E6: Performance Indicator | F6: Resources Needed | H6: Estimated Cost | I6: Account Title | J6: Account Code
F7: Description | G7: Quantity
C8: Regular Expenditure
A9: KRA 1: LEADING STRATEGICALLY | B9: Overhead | C9: Pay monthly electricity bill | D9: Paid electricity of the JHS to ensure continuous provision of electrical supply | E9: # of monthly electricty bills | F9: electrical supply | G9: 1 | H9: 40000 | I9: Electricity Expenses | J9: 5020402000
A10: KRA 1: LEADING STRATEGICALLY | B10: Overhead | C10: Pay monthly landline subscription | D10: Paid landline subscription for teachers and staff with official transactions | E10: # of monthly landline services paid | F10: telephone services | G10: 1 | H10: 2000 | I10: Communication Expenses Landline | J10: 5020202002
A11: KRA 1: LEADING STRATEGICALLY | B11: Overhead | C11: Pay monthly internet subscription | D11: Paid monthly internet connection for academic & administrative use for school learners support services | E11: # of monthly internet services paid | F11: fiber internet | G11: 1 | H11: 2100 | I11: Communication Expenses Internet Subscription | J11: 5020503000
A12: KRA 1: LEADING STRATEGICALLY | B12: Overhead | C12: Pay hired Job Order Utility Personnel | D12: Paid hired job order utility services | E12: # of personnel paid | F12: wages | G12: 2 | H12: 22500 | I12: Other General Services | J12: 50212990000
A13: KRA 1: LEADING STRATEGICALLY | B13: Overhead | C13: Pay annual insurance for school vehicle | D13: Ensured provision of annual insurance premium for school service | E13: # of insurance premium paid | F13: Insurance | G13: 1 | H13: 5000 | I13: Insurance Expenses | J13: 5021503000
A14: KRA 3: FOCUSING ON TEACHING AND LEARNING | B14: Learning and Development | C14: Reimburse registration expenses for JHS teaching and non-teaching personnel in local seminars and training | D14: Reimbursed registration expenses for JHS teaching and non-teaching personnel in local seminars and training | E14: # of reimbursement paid | F14: Reimbursement | G14: 1 | H14: 4000 | I14: Training Expenses | J14: 5020201002
A15: KRA 3: FOCUSING ON TEACHING AND LEARNING | B15: Learning and Development | C15: Reimburse School Travel Expenses-Local and Training Expenses | D15: Reimbursed travelling expenses for JHS teaching and non-teaching personnels in local seminar and trainings | E15: # of reimbursement paid | F15: Reimbursement | G15: 1 | H15: 4000 | I15: Travel Expenses - Local | J15: 5020101000
A16: KRA 1: LEADING STRATEGICALLY | B16: Overhead | C16: Procure fuel for school sevice in submission of school report | D16: Provided transportation for teachers and staff in submission of school report | E16: # of procured fuel for school service | F16: Gasoline | G16: 4 | H16: 5000 | I16: Fuel, Oil, and Lubricants | J16: 5020309000
A17: KRA 2- MANAGING SCHOOL OPERATIONS AND RESOURCES | C17: Pay monthly internet bills | D17: Paid monthly internet connection for academic & administrative use | E17: # of internet bills paid | F17: 5Mbps Internet Connection | G17: 3 | H17: 5000 | I17: Internet Subscription Expenses | J17: 5020503000
A19: KRA 2- MANAGING SCHOOL OPERATIONS AND RESOURCES | C19: Pay electricity bill | D19: Paid monthly electricity bill for the School facilities | E19: # of electricity bills paid | F19: Electricity | G19: 1 | H19: 100000 | I19: Electricity Expenses | J19: 5020402000
A20: KRA 3 - FOCUSING ON TEACHING AND LEARNING | C20: Reimburse travel expense - local and training expenses | D20: Reimbursed registration and travelling expenses in local seminars/trainings of teaching and non-teaching personnel | E20: No. of reimbursement requested | F20: Registration fee and Travelling expenses | G20: 5 | H20: 5000 | I20: Training Expenses | J20: 5020201002
H21: 7148 | I21: Travelling Expenses | J21: 5020101000
C22: SUB-TOTAL | H22: =SUM(H9:H21) -> 201748
C23: Project Related Expenditure
A24: KRA 1: LEADING STRATEGICALLY | B24: Overhead | C24: Pay Tarpaulin Printing | D24: Paid tarpaulin printing for IECA Campaign | E24: # of printed tarpaulin | F24: Tarpaulin | G24: 1 | H24: 6000 | I24: Printing and Publication Expenses | J24: 5029902000
A25: KRA 1: LEADING STRATEGICALLY | B25: GAD | C25: Procure other supplies and materials for Women's Month Celebration | D25: Procured Wellness Massage and Beauty and Nail Care materials for Women's Month Celebration | E25: # of procured supplies and materials | F25: (please see annexes for list of other supplies and materials) | G25: 1 | H25: 7000 | I25: Other Suppplies and Materials Expenses | J25: 5020399000
A26: KRA 1: LEADING STRATEGICALLY | B26: Overhead | C26: Procure supplies and materials for Moving Up Exercises | D26: Procured materials for printing of certificates and other supplies to the completers to ensure 100% completion of JHS students | E26: # of completers | F26: (please see annexes for list of office supplies) | G26: 1 | H26: 30000 | I26: Office Supplies Expenses | J26: 5020301002
F27: (please see annexes for list of other supplies and materials) | G27: 1 | H27: 40000 | I27: Other Suppplies and Materials Expenses | J27: 5020399000
A28: KRA 2- MANAGING SCHOOL OPERATIONS AND RESOURCES | C28: Procure Materials for SHS Graduating Students | D28: Procured materials for the printing of School Forms , Diplomas and other materials to be given to SHS Graduating Students | E28: # of procurement made | G28: 1 | H28: 80000 | I28: Other Supplies & Materials Expenses | J28: 5020399000
A33: KRA 2- MANAGING SCHOOL OPERATIONS AND RESOURCES | C33: Pay Assessment Fee for student assessment of Grade 12 SHS Students | D33: Paid Assessment Fee for student assessment of Grade 12 SHS Students | E33: # of payment made | F33: Dressmaking /Tailoring/ SMAW/CSS/EPAS/FBS/Housekeeping Students | G33: 6 | H33: 51610 | I33: Other Professional Services | J33: 5021199000
A34: KRA 4 - DEVELOPING SELF AND OTHERS | C34: Procure Materials and Other Supplies for Women's Month Celebration | D34: Procured Materials and Other Supplies for Women's Month Celebration | E34: # of payment made | F34: Wellness massage and Beauty Nail Care Supplies | G34: 1 | H34: 1335 | I34: Semi Expendable - Other Machinery & Equipment | J34: 5020321099
H35: 1500 | I35: Semi Expendable - Office Equipment | J35: 5020321002
H36: 12165 | I36: Other Supplies & Materials Expenses | J36: 5020399000
C37: SUB-TOTAL | H37: =SUM(H24:H36) -> 229610
C38: Repair and Maintenance
A39: KRA 1: LEADING STRATEGICALLY | B39: Overhead | C39: Pay maintenance services for online SF9 system | D39: Paid maintenance services for Online SF9 system | E39: # of services maintained | F39: maintenance fee | G39: 1 | H39: 6000 | I39: Other Professional Services | J39: 5021199000
A40: KRA 1: LEADING STRATEGICALLY | B40: Overhead | C40: Procure materials and labor for repair and cleaning of aircon | D40: Procured materials and labor for repair and cleaning of aircon | E40: # of machines/tools maintained | F40: (please see annexes for the list of repair materials) | G40: 1 | H40: 3500 | I40: Repair and Maintenance - Office Equipment | J40: 5021321002
C41: SUB-TOTAL | H41: =SUM(H39:H40) -> 9500
C42: Others
A43: KRA 1: LEADING STRATEGICALLY | B43: Overhead | C43: Pay Taxes and Licenses for Annual Renewal of School Vehicle Registration and Annual Tax Filing | D43: Paid taxes and licenses for Annual Renewal of School Vehicle Registration and Annual Tax Filing | E43: # of taxes and linceses paid | F43: taxes and licenses fee | G43: 2 | H43: 2500 | I43: Taxes and Licenses | J43: 5021501001
A44: KRA 1: LEADING STRATEGICALLY | B44: Monitoring and evaluation processes and tools | C44: Provide Food during School District and Division Activities | D44: Represented the school during SMEA, SOSA, and EXECOM | E44: # of programs and activities | F44: school/district/division | G44: 1 | H44: 7500 | I44: Training Expenses | J44: 5020201002
A45: KRA 1: LEADING STRATEGICALLY | B45: Overhead | C45: Pay Notarial Services for Service Contract Documents | D45: Paid Notarial Services for Service Contract Documents | E45: # of notarial services paid | F45: Notarial Services | G45: 3 | H45: 600 | I45: Legal Services | J45: 5021101000
C46: SUB-TOTAL | H46: =SUM(H43:H45) -> 10600
A48: Total budget for the Month of March 2026 | H48: =H22+H37+H41+H46 -> 451458

Sheet April
A1: LUIS HERVIAS NATIONAL HIGH SCHOOL - JUNIOR HIGH SCHOOL
A3: PROGRAMS/ PROJECTS/ ACTIVITIES, CY 2026
B5: APRIL 2026
A7: Key Result Area based on OPCRF | B7: Programs/Projects/Activities | C7: Purpose / Objectives | D7: Performance Indicator | E7: Resources Needed | G7: Estimated Cost | H7: Account Title | I7: Account Code
E8: Description | F8: Quantity
B9: Regular Expenditure
A10: KRA 1: LEADING STRATEGICALLY | B10: Pay of monthly electricity bill | C10: Paid electricity of the JHS to ensure continuous provision of electrical supply | D10: # of monthly electricty bills | E10: electrical supply | F10: 1 | G10: 40000 | H10: Electricity Expenses | I10: 5020402000
A11: KRA 1: LEADING STRATEGICALLY | B11: Pay monthly landline subscription | C11: Paid landline subscription for teachers and staff with official transactions | D11: # of monthly landline services paid | E11: telephone services | F11: 1 | G11: 2000 | H11: Communication Expenses Landline | I11: 5020202002
A12: KRA 1: LEADING STRATEGICALLY | B12: Pay monthly internet subscription | C12: Paid monthly internet connection for academic & administrative use for school learners support services | D12: # of monthly internet services paid | E12: fiber internet | F12: 1 | G12: 2100 | H12: Communication Expenses Internet Subscription | I12: 5020503000
A13: KRA 1: LEADING STRATEGICALLY | B13: Procure fuel for school sevice in submission of school report | C13: Provided transportation for teachers and staff in submission of school report | D13: # of procured fuel for school service | E13: Gasoline | F13: 4 | G13: 5000 | H13: Fuel, Oil, and Lubricants | I13: 5020309000
A14: KRA 1: LEADING STRATEGICALLY | B14: Pay hired Job Order Utility Personnel | C14: Paid hired job order utility services | D14: # of personnel paid | E14: wages | F14: 2 | G14: 22500 | H14: Other General Services | I14: 50212990000
A15: KRA 2- MANAGING SCHOOL OPERATIONS AND RESOURCES | B15: Pay monthly internet bills | C15: Paid monthly internet connection for academic & administrative use | D15: # of internet bills paid | E15: 5Mbps Internet Connection | F15: 3 | G15: 5000 | H15: Internet Subscription Expenses | I15: 5020503000
A17: KRA 2- MANAGING SCHOOL OPERATIONS AND RESOURCES | B17: Pay electricity bill | C17: Paid monthly electricity bill for the School facilities | D17: # of electricity bills paid | E17: Electricity | F17: 1 | G17: 100000 | H17: Electricity Expenses | I17: 5020402000
A18: KRA 2- MANAGING SCHOOL OPERATIONS AND RESOURCES | B18: Procure Office Supplies and Office Equipment for Senior High Admin. Use | C18: Procured Office Supplies & Materials for office personnel for report generation and submission to oversight agencies and daily office operation | D18: # of procurement made | F18: 1 | G18: 20000 | H18: Office Supplies Expenses | I18: 5020301002
B22: SUB-TOTAL | G22: =SUM(G10:G21) -> 196600
B23: Project Related Expenditure
A24: KRA 3: FOCUSING ON TEACHING AND LEARNING | B24: Train School based teaching and non-teaching personnel of LHNHS thru the conduct of LAC Session | C24: Trained School based teaching and non-teaching personnel of LHNHS thru the conduct of LAC Session for learning and development | D24: # of procured snacks | E24: Snacks | F24: 1 | G24: 10000 | H24: Training Expenses | I24: 5020201002
A25: KRA 2: MANAGING SCHOOL OPERATIONS AND RESOURCES | B25: Procure Janitorial and Disinfection Supplies | C25: Procured janitorial supplies and materials for frontliners and utility personnel | D25: # of procured janitorial and disinfection supplies | E25: (please see annexes for list of janitorial and disinfection supplies ) | F25: 1 | G25: 40000 | H25: Other Supplies and Materials Expenses | I25: 5020399000
A26: KRA 2- MANAGING SCHOOL OPERATIONS AND RESOURCES | B26: Procure Disaster Response Program Materials and Equipment | C26: Procured Semi Expendable Equipment for DRRM Program of SHS teachers to ensure safety and emergency preparedness. | D26: # of procurement made | F26: 1 | G26: 10000 | H26: Semi Expendable - Disaster Response and Rescue Equipment | I26: 5020321008
B28: SUB-TOTAL | G28: =SUM(G24:G27) -> 60000
B29: Repair and Maintenance
A30: KRA 1: LEADING STRATEGICALLY | B30: Procure Materials for Repair and Maintenance of School Furnitures and Fixtures | C30: Procured labor and materials for the repair of chalk board bldg 5 rooms133, 134 232,233 and bldg 17 rooms 122,123,124, 221,222,223 | D30: # of chalk board repaired | E30: please see anexes for list of repairs materials | F30: 1 | G30: 120000 | H30: Repair and Maintenance - Furnitures and Fixtures | I30: 5021322001
A31: KRA 1: LEADING STRATEGICALLY | B31: Procure materials for Repair and Maintenance of Machinery and Equipment | C31: Procured materials and labor for repair of carbon, motor driller, angle grinder and planer | D31: # of machines/tools maintained | E31: (please see annexes for the list of repair materials) | F31: 1 | G31: 3000 | H31: Repair and Maintenance - Other Machinery and Equipment | I31: 5021301099
A32: KRA 2 - MANAGING SCHOOL OPERATIONS AND RESOURCES | B32: Procure labor for the cleaning & maintenance of Semi Expendable - Office Equipment | C32: Procured labor for the cleaning & repair of Aircon in the ICT Laboratory | D32: # of procurement made with labor | E32: 7 units of aircon | F32: 1 | G32: 7200 | H32: Repair & Maintenance - Office Equipment | I32: 5021321002
B33: SUB-TOTAL | G33: =SUM(G30:G32) -> 130200
B34: Others
B35: None
B36: SUB-TOTAL | G36: =SUM(G35) -> 0
A37: Total budget for the Month of April 2026 | G37: =G22+G28+G33 -> 386800

Sheet May
A1: LUIS HERVIAS NATIONAL HIGH SCHOOL - JUNIOR HIGH SCHOOL
A3: PROGRAMS/ PROJECTS/ ACTIVITIES, CY 2026
B5: MAY 2026
A7: Key Result Area based on OPCRF | B7: Programs/Projects/Activities | C7: Purpose / Objectives | D7: Performance Indicator | E7: Resources Needed | G7: Estimated Cost | H7: Account Title | I7: Account Code
E8: Description | F8: Quantity
B9: Regular Expenditure
A10: KRA 1: LEADING STRATEGICALLY | B10: Pay of monthly electricity bill | C10: Paid electricity of the JHS to ensure continuous provision of electrical supply | D10: # of monthly electricty bills | E10: electrical supply | F10: 1 | G10: 30000 | H10: Electricity Expenses | I10: 5020402000
A11: KRA 1: LEADING STRATEGICALLY | B11: Pay monthly landline subscription | C11: Paid landline subscription for teachers and staff with official transactions | D11: # of monthly landline services paid | E11: telephone services | F11: 1 | G11: 2000 | H11: Communication Expenses Landline | I11: 5020202002
A12: KRA 1: LEADING STRATEGICALLY | B12: Pay monthly internet subscription | C12: Paid monthly internet connection for academic & administrative use for school learners support services | D12: # of monthly internet services paid | E12: fiber internet | F12: 1 | G12: 2100 | H12: Communication Expenses Internet Subscription | I12: 5020503000
A13: KRA 1: LEADING STRATEGICALLY | B13: Procure fuel for school sevice in submission of school report | C13: Provided transportation for teachers and staff in submission of school report | D13: # of procured fuel for school service | E13: Gasoline | F13: 4 | G13: 5000 | H13: Fuel, Oil, and Lubricants | I13: 5020309000
A14: KRA 3: FOCUSING ON TEACHING AND LEARNING | B14: Reimburse registration expenses for JHS teaching and non-teaching personnel in local seminars and training | C14: Reimbursed registration expenses for JHS teaching and non-teaching personnel in local seminars and training | D14: # of reimbursement paid | E14: Reimbursement | F14: 1 | G14: 30000 | H14: Training Expenses | I14: 5020201002
A15: KRA 3: FOCUSING ON TEACHING AND LEARNING | B15: Reimburse School Travel Expenses-Local and Training Expenses | C15: Reimbursed travelling expenses for JHS teaching and non-teaching personnels in local seminar and trainings | D15: # of reimbursement paid | E15: Reimbursement | F15: 1 | G15: 30000 | H15: Travel Expenses - Local | I15: 5020101000
A16: KRA 1: LEADING STRATEGICALLY | B16: Procure Purified Drinking Water in compliance to SBM Wins Programs | C16: Procured gallons of purified drinking water to students and personnel | D16: # of procured drinking water | E16: Drinking Water | F16: 1 | G16: 3000 | H16: Other Supplies and Material Expenses | I16: 5020399000
A17: KRA 1: LEADING STRATEGICALLY | B17: Pay hired Job Order Utility Personnel | C17: Paid hired job order utility services | D17: # of personnel paid | E17: wages | F17: 2 | G17: 22500 | H17: Other General Services | I17: 50212990000
A18: KRA 2- MANAGING SCHOOL OPERATIONS AND RESOURCES | B18: Pay monthly internet bills | C18: Paid monthly internet connection for academic & administrative use | D18: # of internet bills paid | E18: 5Mbps Internet Connection | F18: 3 | G18: 5000 | H18: Internet Subscription Expenses | I18: 5020503000
A20: KRA 2- MANAGING SCHOOL OPERATIONS AND RESOURCES | B20: Pay Electricity bills | C20: To provide the electrical supply for the SHS | D20: # of monthly internet bill paid | E20: Electricity | F20: 1 | G20: 70000 | H20: Electricity Expenses | I20: 5020402000
B21: SUB-TOTAL | G21: =SUM(G10:G20) -> 199600
B22: Project Related Expenditure
A23: KRA 1: LEADING STRATEGICALLY | B23: Procure Office Supplies for Admin use | C23: Procured office supplies for Admin and Head Teachers use | D23: # of procured office supplies | E23: (please see annexes for list of supplies) | F23: 1 | G23: 50000 | H23: Office Supplies Expenses | I23: 5020301002
A24: KRA 1: LEADING STRATEGICALLY | B24: Procure office equipment for Admin and Head Teacher use | C24: Procured office equipment for Admin and Head Teachers use | D24: # of procured equipment supplies | E24: (please see annexes for list of supplies) | F24: 1 | G24: 3000 | H24: Office Equipment | I24: 5021321002
A25: KRA 1: LEADING STRATEGICALLY | B25: Procure Clean and Green Project | C25: Procured supplies and materials for Clean and Green Project | D25: # of procured supplies and materials | E25: (please see annexes for the list of supplies and materials) | F25: 1 | G25: 25000 | H25: Other Supplies and Material Expenses | I25: 5020399000
A26: KRA 1: LEADING STRATEGICALLY | B26: Procure materials and equipment for Students' School ID | C26: Procured materials for the school ID of students for identification and security | D26: # of procured materials for the School ID | E26: (please see annexes for other supplies and materials expenses ) | F26: 1 | G26: 3000 | H26: Other Supplies and Materials | I26: 5020399000
A27: KRA 2- MANAGING SCHOOL OPERATIONS AND RESOURCES | B27: Procure Materials for Grade 12 Immersion Program | C27: Procured materials for the printing of immersion documents & other materials needed for the implementation of SHS Grade 12 Immersion | D27: # of procurement made | F27: 1 | G27: 16320 | H27: Other Supplies & Materials Expenses | I27: 5020399000
B28: SUB-TOTAL | G28: =SUM(G23:G27) -> 97320
B29: Repair and Maintenance
A30: KRA 1: LEADING STRATEGICALLY | B30: Provision Materials and Labor for Repair and Maintenance of School Vehicle | C30: Provided materials and labor for repair and maintenance of school vehicle for submission of school reports | D30: # of repaired vehicle | E30: Vehicle | F30: 1 | G30: 10000 | H30: Repair and Maintenance - Motor Vehicle | I30: 5021306001
A31: KRA 1: LEADING STRATEGICALLY | B31: Procure labor and materials for Repair and Maintenance of Water Supply System | C31: Paid labor for broken electric water pump | D31: # of water pump repaired | E31: (please see annexes for the list of repair materials) | F31: 1 | G31: 10000 | H31: Repair and Maintenance - Water Supplies System | I31: 5021303004
A32: KRA 1: LEADING STRATEGICALLY | B32: Procure Materials and Labor of Comfort | C32: Procured materials and labor for repair and improvement of GAD Comfort Rooms at the back of Building no. 13 | D32: # of Comfort Rooms repaired | E32: Comfort Rooms | F32: 1 | G32: 45000 | H32: Repair and Maintenance - Other Structures | I32: 5021304099
A33: KRA 1: LEADING STRATEGICALLY | B33: Procure Materials and Labor of Comfort Rooms | C33: Procured materials and labor for repair and improvement of GAD Comfort Rooms beside bldg no. 8 | D33: # of Comfort Rooms repaired | E33: Comfort Rooms | F33: 1 | G33: 35000 | H33: Repair and Maintenance - Other Structures | I33: 5021304099
A34: KRA 2 - MANAGING SCHOOL OPERATIONS AND RESOURCES | B34: Procure materials with labor for classroom in SHS building room #221,222,223, 2 - storey building #17. | D34: No. of procurement made for materials and labor | F34: 1 | G34: 25000 | H34: Repair and Maintenance - School Building | I34: 50213040002
F35: 1
A36: KRA 1 - LEADING STRATEGICALLY | B36: Procure materials with labor for the repair classroom in SHS building #19. | D36: # of procurement made | F36: 1 | G36: 40000 | H36: Repair and Maintenance - School Building | I36: 50213040002
F37: 1
A38: KRA 1 - LEADING STRATEGICALLY | B38: Procure materials with labor for the repair & maintenance of Comfort Rooms of building 19. | D38: # of procurement made | F38: 1 | G38: 84400 | H38: Repair and Maintenance - School Building | I38: 50213040002
F39: 1
B40: SUB-TOTAL | G40: =SUM(G30:G39) -> 249400
B41: Others
B42: SUB-TOTAL
A43: Total budget for the Month of May 2026 | G43: =G21+G28+G40 -> 546320

Sheet June
A1: LUIS HERVIAS NATIONAL HIGH SCHOOL - JUNIOR HIGH SCHOOL
A3: PROGRAMS/ PROJECTS/ ACTIVITIES, CY 2026
B5: JUNE 2026
A7: Key Result Area based on OPCRF | B7: Programs/Projects/Activities | C7: Purpose / Objectives | D7: Performance Indicator | E7: Resources Needed | G7: Estimated Cost | H7: Account Title | I7: Account Code
E8: Description | F8: Quantity
B9: Regular Expenditure
A10: KRA 1: LEADING STRATEGICALLY | B10: Pay of monthly electricity bill | C10: Paid electricity of the JHS to ensure continuous provision of electrical supply | D10: # of monthly electricty bills | E10: electrical supply | F10: 1 | G10: 30000 | H10: Electricity Expenses | I10: 5020402000
A11: KRA 1: LEADING STRATEGICALLY | B11: Pay monthly landline subscription | C11: Paid landline subscription for teachers and staff with official transactions | D11: # of monthly landline services paid | E11: telephone services | F11: 1 | G11: 2000 | H11: Communication Expenses Landline | I11: 5020202002
A12: KRA 1: LEADING STRATEGICALLY | B12: Pay monthly internet subscription | C12: Paid monthly internet connection for academic & administrative use for school learners support services | D12: # of monthly internet services paid | E12: fiber internet | F12: 1 | G12: 2100 | H12: Communication Expenses Internet Subscription | I12: 5020503000
A13: KRA 1: LEADING STRATEGICALLY | B13: Pay hired Job Order Utility Personnel | C13: Paid hired job order utility services | D13: # of personnel paid | E13: wages | F13: 2 | G13: 22500 | H13: Other General Services | I13: 50212990000
A14: KRA 3: FOCUSING ON TEACHING AND LEARNING | B14: Reimburse registration expenses for JHS teaching and non-teaching personnel in local seminars and training | C14: Reimbursed registration expenses for JHS teaching and non-teaching personnel in local seminars and training | D14: # of reimbursement paid | E14: Reimbursement | F14: 1 | G14: 25000 | H14: Training Expenses | I14: 5020201002
A15: KRA 3: FOCUSING ON TEACHING AND LEARNING | B15: Reimburse School Travel Expenses-Local and Training Expenses | C15: Reimbursed travelling expenses for JHS teaching and non-teaching personnels in local seminar and trainings | D15: # of reimbursement paid | E15: Reimbursement | F15: 1 | G15: 25000 | H15: Travel Expenses - Local | I15: 5020101000
A16: KRA 1: LEADING STRATEGICALLY | B16: Procure fuel for school sevice in submission of school report | C16: Provided transportation for teachers and staff in submission of school report | D16: # of procured fuel for school service | E16: Gasoline | F16: 4 | G16: 5000 | H16: Fuel, Oil, and Lubricants | I16: 5020309000
A17: KRA 2- MANAGING SCHOOL OPERATIONS AND RESOURCES | B17: Pay monthly internet bills | C17: Paid monthly internet connection for academic & administrative use | D17: # of internet bills paid | E17: 5Mbps Internet Connection | F17: 3 | G17: 5000 | H17: Internet Subscription Expenses | I17: 5020503000
A19: KRA 2- MANAGING SCHOOL OPERATIONS AND RESOURCES | B19: Pay Electricity bills | C19: To provide the electrical supply for the SHS | D19: # of monthly internet bill paid | E19: Electricity | F19: 1 | G19: 70000 | H19: Electricity Expenses | I19: 5020402000
A20: KRA 3 - FOCUSING ON TEACHING AND LEARNING | B20: Reimburse travel expense - local and training expenses | C20: Reimbursed registration and travelling expenses in local seminars/trainings of teaching and non-teaching personnel | D20: No. of reimbursement requested | E20: Registration fee and Travelling expenses | F20: 5 | G20: 10000 | H20: Training Expenses | I20: 5020201002
G21: 10000 | H21: Travelling Expenses | I21: 5020101000
B22: SUB-TOTAL | G22: =SUM(G10:G21) -> 206600
B23: Project Related Expenditure
A25: KRA 1: LEADING STRATEGICALLY | B25: Pay Tarpaulin Printing | C25: Paid tarpaulin printing for IECA Campaign | D25: # of printed tarpaulin | E25: Tarpaulin | F25: 1 | G25: 6000 | H25: Printing and Publication Expenses | I25: 5029902000
A26: KRA 1: LEADING STRATEGICALLY | B26: Procure furniture and fixtures for Records Office | C26: Procured cabinet for safe keeping of school records of students | D26: # of procured cabinet | E26: (please see annexes for furniture and fixtures) | F26: 2 | G26: 30000 | H26: Semi-Expendable - ICT Equipment | I26: 5020321003
A27: KRA 3: FOCUSING ON TEACHING AND LEARNING | B27: Procure meals for Teaching and Non-teaching Personnel for GAD Training | C27: Procured food Teaching and Non-teaching Personnel for Gender and Development Training | D27: # of procured meals | E27: Morning snacks and Lunch , | F27: 1 | G27: 30000 | H27: Training Expenses | I27: 5020201002
A28: KRA 1 - LEADING STRATEGICALLY | B28: Pay maintenance services for online SF9 system | C28: Paid maintenance services for online SF9 system | D28: # of services maintained | E28: maintenance fee | F28: 1 | G28: 6000 | H28: Other Professional Services | I28: 5021199000
B29: Training for Gender and Development Program with provision of foods | G29: 21100
B30: SUB-TOTAL | G30: =SUM(G25:G29) -> 93100
B31: Repair and Maintenance
A32: KRA 1: LEADING STRATEGICALLY | B32: Pay maintenance services for online SF9 system | C32: Paid maintenance services for Online SF9 system | D32: # of services maintained | E32: maintenance fee | F32: 1 | G32: 6000 | H32: Other Professional Services | I32: 5021199000
A33: KRA 1: LEADING STRATEGICALLY | B33: Procure Materials and Labor for Repair and Maintenance of ICT Equipment | C33: Procured materials and labor for repair and maintenance of ict equipment | D33: # of ict equipment repaired | E33: (please see annexes for the list of repair materials) | F33: 1 | G33: 15000 | H33: Repairs and Maintenance - Semi-Expendable Machinery and Equipment-Information and Communication Technology Equipment | I33: 5021321003
B34: Procure materials with labor for the repair and maintenance of Grinder | F34: 1 | G34: 22600
B35: SUB-TOTAL | G35: =SUM(G32:G34) -> 43600
B36: Others
A37: KRA 1: LEADING STRATEGICALLY | B37: Provide Food during School District and Division Activities | C37: Represented the school during SMEA, SOSA, and EXECOM | D37: # of programs and activities | E37: school/district/ division | F37: 1 | G37: 7500 | H37: Training Expenses | I37: 5020201002
B38: SUB-TOTAL | G38: =SUM(G37:G37) -> 7500
A40: Total budget for the Month of June 2026 | G40: =G22+G30+G35+G38 -> 350800

Sheet July
A1: LUIS HERVIAS NATIONAL HIGH SCHOOL - JUNIOR HIGH SCHOOL
A3: PROGRAMS/ PROJECTS/ ACTIVITIES, CY 2026
B5: JULY 2026
A7: Key Result Area based on OPCRF | B7: Programs/Projects/Activities | C7: Purpose / Objectives | D7: Performance Indicator | E7: Resources Needed | G7: Estimated Cost | H7: Account Title | I7: Account Code
E8: Description | F8: Quantity
B9: Regular Expenditure
A10: KRA 1: LEADING STRATEGICALLY | B10: Pay of monthly electricity bill | C10: Paid electricity of the JHS to ensure continuous provision of electrical supply | D10: # of monthly electricty bills | E10: electrical supply | F10: 1 | G10: 40000 | H10: Electricity Expenses | I10: 5020402000
A11: KRA 1: LEADING STRATEGICALLY | B11: Pay monthly landline subscription | C11: Paid landline subscription for teachers and staff with official transactions | D11: # of monthly landline services paid | E11: telephone services | F11: 1 | G11: 2000 | H11: Communication Expenses Landline | I11: 5020202002
A12: KRA 1: LEADING STRATEGICALLY | B12: Pay monthly internet subscription | C12: Paid monthly internet connection for academic & administrative use for school learners support services | D12: # of monthly internet services paid | E12: fiber internet | F12: 1 | G12: 2100 | H12: Communication Expenses Internet Subscription | I12: 5020503000
A13: KRA 1: LEADING STRATEGICALLY | B13: Procure fuel for school sevice in submission of school report | C13: Provided transportation for teachers and staff in submission of school report | D13: # of procured fuel for school service for | E13: Gasoline | F13: 4 | G13: 5000 | H13: Fuel, Oil, and Lubricants | I13: 5020309000
A14: KRA 1: LEADING STRATEGICALLY | B14: Pay hired Job Order Utility Personnel | C14: Paid hired job order utility services | D14: # of personnel paid | E14: wages | F14: 2 | G14: 22500 | H14: Other General Services | I14: 50212990000
A15: KRA 2- MANAGING SCHOOL OPERATIONS AND RESOURCES | B15: Pay monthly internet bills | C15: Paid monthly internet connection for academic & administrative use | D15: # of internet bills paid | E15: 5Mbps Internet Connection | F15: 3 | G15: 5000 | H15: Internet Subscription Expenses | I15: 5020503000
A17: KRA 2 - MANAGING SCHOOL OPERATIONS AND RESOURCES | B17: Pay Electricity bills | C17: To provide the electrical supply for the SHS | D17: # of monthly internet bill paid | E17: Electricity | F17: 1 | G17: 80000 | H17: Electricity Expenses | I17: 5020402000
B18: SUB-TOTAL | G18: =SUM(G10:G17) -> 156600
B19: Project Related Expenditure
A20: KRA 2: MANAGING SCHOOL OPERATIONS AND RESOURCES | B20: Procure Medicines and Vitamins | C20: Procured medicines and vitamins for the treatment of minor illness and to boost the immune system of teachers, students and personnel | D20: # of procured medicines and vitamins | E20: (please see annexes for list of medicines and vitamins) | F20: 1 | G20: 15000 | H20: Drugs and Medicines Expenses | I20: 5020307000
A21: KRA 1: LEADING STRATEGICALLY | B21: Procure of materials for the printing of 1st and 2nd Quarterly Assessment of students | C21: Procured printing materials for the 1st and 2nd Quarterly Assessment of students | D21: # of procured printing materials | E21: Bondpapers | F21: 240 reams | G21: 60000 | H21: Office Supplies Expenses | I21: 5020301002
E22: Toner | F22: 12 | G22: 50000 | H22: Office Supplies Expenses | I22: 5020301002
E23: Master stencils | F23: 6 | H23: Office Supplies Expenses | I23: 5020301002
A24: KRA 3 - FOCUSING ON TEACHING AND LEARNING | B24: Reimburse travelling expenses of SHS Teachers for Immersion | C24: Reimburse travelling expenses of SHS Teachers for Immersion of SHS students | D24: No. of reimbursement requested | E24: Registration fee and Travelling expenses | F24: 10 | G24: 5000 | H24: Travelling Expenses | I24: 5020101000
A25: KRA 2- MANAGING SCHOOL OPERATIONS AND RESOURCES | B25: Procure materials for the printing of Quarterly Assessment for SHS | C25: Procured materials for the printing of Summative Assessment of SHS in the 3rd & 4th Quarter | D25: # of procurement made | F25: 1 | G25: 100000 | H25: Office Supplies Expenses | I25: 5020301002
A28: KRA 2- MANAGING SCHOOL OPERATIONS AND RESOURCES | B28: Procure Semi-Expendable ICT Equipment for HUMSS | C28: Procured ICT equipment for HUMSS Teacher | D28: # of procurement made | F28: 1 | G28: 10000 | H28: Semi Expendable - ICT Equipment | I28: 5020321003
B29: Procure Expendable materials & ICT Equipment for Contact Center Services and Medical Transcription | C29: Procured materials and ICT Equipment to improve the ICT related skills of CCS and Medical Transcription students SHS students | D29: # of procurement made | F29: 1 | G29: 10000 | H29: Semi Expendable - ICT Equipment | I29: 5020321003
A30: KRA 2- MANAGING SCHOOL OPERATIONS AND RESOURCES | B30: Procure Expendable materials & Equipment for BNC | C30: Procure Expendable materials & Equipment for BNC | D30: # of procurement made | F30: 1 | G30: 10000 | H30: Semi Expendable - Other Machinery & Equipment | I30: 5020321099
H32: Other Supplies & Materials | I32: 5020399000
A35: KRA 2- MANAGING SCHOOL OPERATIONS AND RESOURCES | B35: Procure ICT supplies and equipment for Senior High EPAS | C35: Procured ICT supplies & equipment for the performance task of students in preparation of TESDA Assessment | D35: # of procurement made | F35: 1 | G35: 20000 | H35: Semi Expendable - ICT Equipment | I35: 5020321003
A37: KRA 2 - MANAGING SCHOOL OPERATIONS AND RESOURCES | B37: Procure Medical Supplies | C37: Procured medical supplies for the treatment of minor injury and safety precaution against sickness | D37: No. of procurement made | F37: 1 | H37: Medical Dental & Laboratoty Supplies Expense | I37: 5020308000
A39: KRA 2 - MANAGING SCHOOL OPERATIONS AND RESOURCES | B39: Procure Medicine & Semi Expendable - Equipment for the School Clinic | C39: Procured medicine and equipment for the treatment of minor illness for SHS teachers and students | D39: No. of procurement made | F39: 1 | G39: 10000 | H39: Semi Expendable - Other Machinery & Equipment Expense | I39: 5020321099
H41: Drug & Medicines Expenses | I41: 5020307000
B45: SUB-TOTAL | G45: =SUM(G20:G44) -> 290000
B46: Repair and Maintenance
A47: KRA 1: LEADING STRATEGICALLY | B47: Procure materials and labor for repair of office equipment | C47: Procured materials and labor for repair of office equipment | D47: # of machines/tools maintained | E47: (please see annexes for the list of repair materials) | F47: 1 | G47: 1000 | H47: Repair and Maintenance - Office Equipment | I47: 5021321002
A48: KRA 1: LEADING STRATEGICALLY | B48: Procure Materials for Repair and Maintenance of School Furnitures and Fixtures | C48: Procured labor and materials for the repair of furniture and fixtures | D48: # of ceiling and doors repaired | E48: please see anexes for list of repairs materials | F48: 2 | G48: 60000 | H48: Repair and Maintenance - Furnitures and Fixtures | I48: 5021322001
A49: KRA 1: LEADING STRATEGICALLY | B49: Procure Materials and Labor for Repair and Maintenance of Printing Equipment | C49: Procured materials and labor for repair and maintenance of printing equipment | D49: # of printers repaired | E49: (please see annexes for the list of repair materials) | F49: 1 | G49: 6000 | H49: Repair and Maintenance - Printing Equipment | I49: 5021321011
B50: SUB-TOTAL | G50: =SUM(G47:G49) -> 67000
B51: Others
B52: NONE
A53: Total budget for the Month of July 2026 | G53: =G18+G45+G50 -> 513600

Sheet August
A1: LUIS HERVIAS NATIONAL HIGH SCHOOL - JUNIOR HIGH SCHOOL
A3: PROGRAMS/ PROJECTS/ ACTIVITIES, CY 2026
B5: AUGUST 2026
A7: Key Result Area based on OPCRF | B7: Programs/Projects/Activities | C7: Purpose / Objectives | D7: Performance Indicator | E7: Resources Needed | G7: Estimated Cost | H7: Account Title | I7: Account Code
E8: Description | F8: Quantity
B9: Regular Expenditure
A10: KRA 1: LEADING STRATEGICALLY | B10: Pay of monthly electricity bill | C10: Paid electricity of the JHS to ensure continuous provision of electrical supply | D10: # of monthly electricty bills | E10: electrical supply | F10: 1 | G10: 40000 | H10: Electricity Expenses | I10: 5020402000
A11: KRA 1: LEADING STRATEGICALLY | B11: Pay monthly landline subscription | C11: Paid landline subscription for teachers and staff with official transactions | D11: # of monthly landline services paid | E11: telephone services | F11: 1 | G11: 2000 | H11: Communication Expenses Landline | I11: 5020202002
A12: KRA 1: LEADING STRATEGICALLY | B12: Pay monthly internet subscription | C12: Paid monthly internet connection for academic & administrative use for school learners support services | D12: # of monthly internet services paid | E12: fiber internet | F12: 1 | G12: 2100 | H12: Communication Expenses Internet Subscription | I12: 5020503000
A13: KRA 1: LEADING STRATEGICALLY | B13: Procure fuel for school sevice in submission of school report | C13: Provided transportation for teachers and staff in submission of school report | D13: # of procured fuel for schoolservice | E13: Gasoline | F13: 4 | G13: 5000 | H13: Fuel, Oil, and Lubricants | I13: 5020309000
A14: KRA 3: FOCUSING ON TEACHING AND LEARNING | B14: Reimburse registration expenses for JHS teaching and non-teaching personnel in local seminars and training | C14: Reimbursed registration expenses for JHS teaching and non-teaching personnel in local seminars and training | D14: # of reimbursement paid | E14: Reimbursement | F14: 1 | G14: 10000 | H14: Training Expenses | I14: 5020201002
A15: KRA 3: FOCUSING ON TEACHING AND LEARNING | B15: Reimburse School Travel Expenses-Local and Training Expenses | C15: Reimbursed travelling expenses for JHS teaching and non-teaching personnels in local seminar and trainings | D15: # of reimbursement paid | E15: Reimbursement | F15: 1 | G15: 15000 | H15: Travel Expenses - Local | I15: 5020101000
A16: KRA 1: LEADING STRATEGICALLY | B16: Procure Purified Drinking Water in compliance to SBM Wins Programs | C16: Procured gallons of purified drinking water to students and personnel | D16: # of procured drinking water | E16: Drinking Water | F16: 1 | G16: 3000 | H16: Other Supplies and Material Expenses | I16: 5020399000
A17: KRA 1: LEADING STRATEGICALLY | B17: Pay hired Job Order Utility Personnel | C17: Paid hired job order utility services | D17: # of personnel paid | E17: wages | F17: 2 | G17: 22500 | H17: Other General Services | I17: 50212990000
A18: KRA 2- MANAGING SCHOOL OPERATIONS AND RESOURCES | B18: Pay monthly internet bills | C18: Paid monthly internet connection for academic & administrative use | D18: # of internet bills paid | E18: 5Mbps Internet Connection | F18: 3 | G18: 5000 | H18: Internet Subscription Expenses | I18: 5020503000
A20: KRA 2 - MANAGING SCHOOL OPERATIONS AND RESOURCES | B20: Pay Electricity bills | C20: To provide the electrical supply for the SHS | D20: # of monthly internet bill paid | E20: Electricity | F20: 1 | G20: 100000 | H20: Electricity Expenses | I20: 5020402000
B21: SUB-TOTAL | G21: =SUM(G10:G20) -> 204600
B22: Project Related Expenditure
A23: KRA 2: MANAGING SCHOOL OPERATIONS AND RESOURCES | B23: Procure Janitorial and Disinfection Supplies | C23: Procured janitorial supplies and materials for frontliners and utility personnel | D23: # of procured janitorial and disinfection supplies | E23: (please see annexes for list of janitorial and disinfection supplies ) | F23: 1 | G23: 40000 | H23: Other Supplies and Materials Expenses | I23: 5020399000
A24: KRA 2 - MANAGING SCHOOL OPERATIONS AND RESOURCES | B24: Literacy and Academic performance Building through Utilization of Technology Access and Ways (LABUTAW) | C24: Procured additional equipment for LR & Library Program | D24: # of procurement made | F24: 1 | G24: 15000 | H24: Semi Expendable - Office Equipment | I24: 5020321002
H25: Semi Expendable - Furnitures & Fixtures | I25: 5020322001
H28: Semi Expendable - ICT Equipment | I28: 5020321003
A29: KRA 3 - FOCUSING ON TEACHING AND LEARNING | B29: GAWAD AGILA | C29: Procured materials for the teaching and non-teaching personnel Awardees of LHNHS 2025 GAWAD AGILA | D29: # of procurement made | F29: 1 | G29: 25000 | H29: Other Supplies & Materials | I29: 5020399000
B32: SUB-TOTAL | G32: =SUM(G23:G31) -> 80000
B33: Repair and Maintenance
A34: KRA 1: LEADING STRATEGICALLY | B34: Procure Materials and Labor of Comfort Rooms | C34: Procured materials and labor for repair and improvement of GAD Bagong Lipunan Comfort Rooms | D34: # of Comfort Rooms repaired | E34: Comfort Rooms | F34: 1 | G34: 45000 | H34: Repair and Maintenance - Other Structures | I34: 5021304099
A35: KRA 1: LEADING STRATEGICALLY | B35: Procure Materials and Labor for Repair and Maintenance of Math Center | C35: Procured materials and labor for repair and maintenance of Math Center | D35: # of Math Center repaired | E35: please see anexes for list of repairs materials | F35: 1 | G35: 50000 | H35: Repair and Maintenance - Other Structures | I35: 5021304099
A36: KRA 1: LEADING STRATEGICALLY | B36: Procure labor and materials for Repair and Maintenance of Water Supply System | C36: Paid labor for broken electric water pump | D36: # of water pump repaired | E36: (please see annexes for the list of repair materials) | F36: 1 | G36: 10000 | H36: Repair and Maintenance - Water Supplies System | I36: 5021303004
A37: KRA 1: LEADING STRATEGICALLY | B37: Procure Materials and Labor for Repair and Maintenance of Printing Equipment | C37: Procured materials and labor for repair and maintenance of printing equipment | D37: # of printers repaired | E37: (please see annexes for the list of repair materials) | F37: 1 | G37: 6000 | H37: Repair and Maintenance - Printing Equipment | I37: 5021321011
A38: KRA 1: LEADING STRATEGICALLY | B38: Provision Materials and Labor for Repair and Maintenance of School Vehicle | C38: Provided materials and labor for repair and maintenance of school vehicle for submission of school reports | D38: # of repaired vehicle | E38: Vehicle | F38: 1 | G38: 20000 | H38: Repair and Maintenance - Motor Vehicle | I38: 5021306001
B39: SUB-TOTAL | G39: =SUM(G34:G38) -> 131000
B40: Others
B41: None
A43: Total budget for the Month of August 2026 | G43: =G21+G32+G39 -> 415600

Sheet September
A1: LUIS HERVIAS NATIONAL HIGH SCHOOL - JUNIOR HIGH SCHOOL
A3: SCHOOL IMPLEMENTATION PLAN, CY 2026
B5: SEPTEMBER 2026
A7: Key Result Area based on OPCRF | B7: Programs/Projects/Activities | C7: Purpose / Objectives | D7: Performance Indicator | E7: Resources Needed | G7: Estimated Cost | H7: Account Title | I7: Account Code
E8: Description | F8: Quantity
B9: Regular Expenditure
A10: KRA 1: LEADING STRATEGICALLY | B10: Pay of monthly electricity bill | C10: Paid electricity of the JHS to ensure continuous provision of electrical supply | D10: # of monthly electricty bills | E10: electrical supply | F10: 1 | G10: 40000 | H10: Electricity Expenses | I10: 5020402000
A11: KRA 1: LEADING STRATEGICALLY | B11: Pay monthly landline subscription | C11: Paid landline subscription for teachers and staff with official transactions | D11: # of monthly landline services paid | E11: telephone services | F11: 1 | G11: 2000 | H11: Communication Expenses Landline | I11: 5020202002
A12: KRA 1: LEADING STRATEGICALLY | B12: Pay monthly internet subscription | C12: Paid monthly internet connection for academic & administrative use for school learners support services | D12: # of monthly internet services paid | E12: fiber internet | F12: 1 | G12: 2100 | H12: Communication Expenses Internet Subscription | I12: 5020503000
A13: KRA 1: LEADING STRATEGICALLY | B13: Pay hired Job Order Utility Personnel | C13: Paid hired job order utility services | D13: # of personnel paid | E13: wages | F13: 2 | G13: 22500 | H13: Other General Services | I13: 50212990000
A14: KRA 3: FOCUSING ON TEACHING AND LEARNING | B14: Reimburse registration expenses for JHS teaching and non-teaching personnel in local seminars and training | C14: Reimbursed registration expenses for JHS teaching and non-teaching personnel in local seminars and training | D14: # of reimbursement paid | E14: Reimbursement | F14: 1 | G14: 20000 | H14: Training Expenses | I14: 5020201002
