Workbook
Name Awards_Rewards_and_Prizes: links!$K$84:$K$86
Name CO: links!$B$2:$B$3
Name Communication_Expenses: links!$K$79:$K$83
Name Confidential__Intelligence_and_Extraordinary_Expenses: links!$K$93
Name Demolition_Relocation_and_Desilting_Dredging_Expenses: links!$K$90
Name Financial_Assistance_Subsidy: links!$K$157:$K$163
Name General_Services: links!$K$99:$K$103
Name Generation__Transmission_and_Distribution_Expenses: links!$K$91:$K$92
Name Intangible_Assets_Outlay: links!$K$220:$K$222
Name Labor_and_Wages: links!$K$168
Name MOOE: links!$B$4:$B$20
Name Other_Compensation: links!$K$4:$K$25
Name Other_Maintenance_and_Operating_Expenses: links!$K$169:$K$191
Name Other_Personnel_Benefits: links!$K$30:$K$41
Name Personnel_Benefit_Contributions: links!$K$26:$K$29
Name Professional_Services: links!$K$94:$K$98
Name Property__Plant_and_Equipment_Outlay: links!$K$192:$K$219
Name PS: links!$B$21:$B$24
Name Repairs_and_Maintenance: links!$K$104:$K$156
Name Salaries_and_Wages: links!$K$2:$K$3
Name Supplies_and_Materials_Expenses: links!$K$47:$K$76
Name Survey__Research__Exploration_and_Development_Expenses: links!$K$87:$K$89
Name Taxes__Insurance_Premiums_and_Other_Fees: links!$K$164:$K$167
Name Training_and_Scholarship_Expenses: links!$K$44:$K$46
Name Traveling_Expenses: links!$K$42:$K$43
Name Utility_Expenses: links!$K$77:$K$78

Sheet Expenditure Form
A1: Department of Education
A3: Office Code : | B3: 302709 | BU3: 302709
A4: Office Name : | B4: Luis Hervias National High School
A5: Fiscal Year : | B5: 2026
A7: =CONCATENATE("FY ",B5," EXPENDITURE FORM") -> FY 2026 EXPENDITURE FORM
A9: PAP | B9: KRA | C9: Specific Program | D9: Output | E9: Output Priority Rank | F9: Output Milestone | G9: Activities | H9: Performance Indicator | I9: Expense Class (PS /MOOE/ CO) | J9: Expense Object DBM Grouping | L9: GAA by Object | N9: Expense Item | O9: COSTING | S9: Location for TEV | T9: PPMP (Y/N) | U9: APP-Supplies (Y/N) | V9: APP-Airline Ticket (Y/N) | W9: Manner of Release (Downloading, Cash Advance, Direct Payment) | X9: =CONCATENATE("FY ",B5-1," Physical Target") -> FY 2025 Physical Target | AE9: =CONCATENATE("FY ",B5," Physical Target") -> FY 2026 Physical Target | AR9: =CONCATENATE("FY ",B5," FINANCIAL OBLIGATION PROGRAM") -> FY 2026 FINANCIAL OBLIGATION PROGRAM | BE9: =CONCATENATE("FY ",B5," FINANCIAL DISBURSEMENT PROGRAM") -> FY 2026 FINANCIAL DISBURSEMENT PROGRAM | BR9: =CONCATENATE("FY ",B5+1," FINANCIAL DISBURSEMENT PROGRAM") -> FY 2027 FINANCIAL DISBURSEMENT PROGRAM | BV9: For Clearance Review
O10: Quantity | P10: Unit Cost | Q10: Frequency | R10: Total Amount | X10: Total Physical Target | Y10: Q3 | AB10: Q4 | AE10: Total Physical Target | AF10: Q1 | AI10: Q2 | AL10: Q3 | AO10: Q4 | AR10: Total Obligation | AS10: Q1 | AV10: Q2 | AY10: Q3 | BB10: Q4 | BE10: Total Disbursement | BF10: Q1 | BI10: Q2 | BL10: Q3 | BO10: Q4 | BR10: Total Disbursement | BS10: Q1
Y11: July | Z11: Aug. | AA11: Sept. | AB11: Oct. | AC11: Nov. | AD11: Dec. | AF11: Jan. | AG11: Feb. | AH11: Mar. | AI11: Apr. | AJ11: May | AK11: June | AL11: July | AM11: Aug. | AN11: Sept. | AO11: Oct. | AP11: Nov. | AQ11: Dec. | AS11: Jan. | AT11: Feb. | AU11: Mar. | AV11: Apr. | AW11: May | AX11: June | AY11: July | AZ11: Aug. | BA11: Sept. | BB11: Oct. | BC11: Nov. | BD11: Dec. | BF11: Jan. | BG11: Feb. | BH11: Mar. | BI11: Apr. | BJ11: May | BK11: June | BL11: July | BM11: Aug. | BN11: Sept. | BO11: Oct. | BP11: Nov. | BQ11: Dec. | BS11: Jan. | BT11: Feb. | BU11: Mar.
A12: 310400100003000 - Operation of Schools - Junior High School (Grade 7 to Grade 10) (Total Budget Cost :3,085,000.00) | BW12: 69 | BX12: 71127 | BY12: 2026
C13: Pillar 5:Monitoring and evaluation processes and tools | K13: =VLOOKUP(J13,links!B$2:C$24,2,FALSE) -> #N/A | BY13: =IF(ISBLANK(C13),0,1) -> 1 | BZ13: =IF(ISBLANK(D13),0,1) -> 0 | CA13: =IF(ISBLANK(F13),0,1) -> 0 | CB13: =IF(ISBLANK(G13),0,1) -> 0 | CC13: =IF(ISBLANK(N13),0,1) -> 0
D14: Submitted SMEA reports | E14: 1 | H14: No. of SMEA reports submitted | K14: =VLOOKUP(J14,links!B$2:C$24,2,FALSE) -> #N/A | X14: =SUM(Y14:AD14) -> 0 | AE14: =SUM(AF14:AQ14) -> 4 | AH14: 1 | AK14: 1 | AN14: 1 | AQ14: 1 | BY14: =IF(ISBLANK(C14),0,1) -> 0 | BZ14: =IF(ISBLANK(D14),0,1) -> 1 | CA14: =IF(ISBLANK(F14),0,1) -> 0 | CB14: =IF(ISBLANK(G14),0,1) -> 0 | CC14: =IF(ISBLANK(N14),0,1) -> 0
G15: Conduct Execom Meeting | H15: No. of Execom meeting conducted | K15: =VLOOKUP(J15,links!B$2:C$24,2,FALSE) -> #N/A | R15: =R16 -> 10000 | X15: =SUM(Y15:AD15) -> 0 | AE15: =SUM(AF15:AQ15) -> 4 | AH15: 1 | AK15: 1 | AN15: 1 | AQ15: 1 | AR15: =AR16 -> 10000 | AS15: =AS16 -> 0 | AT15: =AT16 -> 0 | AU15: =AU16 -> 2500 | AV15: =AV16 -> 0 | AW15: =AW16 -> 0 | AX15: =AX16 -> 2500 | AY15: =AY16 -> 0 | ... BQ15: =BQ16 -> 2500 | BY15: =IF(ISBLANK(C15),0,1) -> 0 | BZ15: =IF(ISBLANK(D15),0,1) -> 0 | CA15: =IF(ISBLANK(F15),0,1) -> 0 | CB15: =IF(ISBLANK(G15),0,1) -> 1 | CC15: =IF(ISBLANK(N15),0,1) -> 0
I16: MOOE | J16: Training and Scholarship Expenses | K16: =VLOOKUP(J16,[1]links!B$2:C$24,2,FALSE) -> Training_and_Scholarship_Expenses | L16: Training Expenses | M16: =VLOOKUP(L16,[1]links!K$2:L$222,2,FALSE) -> 44 | N16: snacks for the conduct of Execom Meeting | O16: 1 | P16: 2500 | Q16: 4 | R16: =O16*P16*Q16 -> 10000 | T16: Y | U16: N | V16: N | W16: Direct Payment | AR16: =SUM(AS16:BD16) -> 10000 | AU16: 2500 | AX16: 2500 | BA16: 2500 | BD16: 2500 | BE16: =SUM(BF16:BQ16) -> 10000 | BH16: 2500 | BK16: 2500 | BN16: 2500 | BQ16: 2500 | BY16: =IF(ISBLANK(C16),0,1) -> 0 | BZ16: =IF(ISBLANK(D16),0,1) -> 0 | CA16: =IF(ISBLANK(F16),0,1) -> 0 | CB16: =IF(ISBLANK(G16),0,1) -> 0 | CC16: =IF(ISBLANK(N16),0,1) -> 1
G17: Conduct SMEA presentation | H17: No. of SMEA presentation conducted | K17: =VLOOKUP(J17,links!B$2:C$24,2,FALSE) -> #N/A | R17: =R18 -> 20000 | X17: =SUM(Y17:AD17) -> 0 | AE17: =SUM(AF17:AQ17) -> 4 | AH17: 1 | AK17: 1 | AN17: 1 | AQ17: 1 | AR17: =AR18 -> 20000 | AS17: =AS18 -> 0 | AT17: =AT18 -> 0 | AU17: =AU18 -> 5000 | AV17: =AV18 -> 0 | AW17: =AW18 -> 0 | AX17: =AX18 -> 5000 | AY17: =AY18 -> 0 | ... BQ17: =BQ18 -> 5000 | BY17: =IF(ISBLANK(C17),0,1) -> 0 | BZ17: =IF(ISBLANK(D17),0,1) -> 0 | CA17: =IF(ISBLANK(F17),0,1) -> 0 | CB17: =IF(ISBLANK(G17),0,1) -> 1 | CC17: =IF(ISBLANK(N17),0,1) -> 0
I18: MOOE | J18: Training and Scholarship Expenses | K18: =VLOOKUP(J18,[1]links!B$2:C$24,2,FALSE) -> Training_and_Scholarship_Expenses | L18: Training Expenses | M18: =VLOOKUP(L18,[1]links!K$2:L$222,2,FALSE) -> 44 | N18: snacks for the conduct of SMEA presentation | O18: 1 | P18: 5000 | Q18: 4 | R18: =O18*P18*Q18 -> 20000 | T18: Y | U18: N | V18: N | W18: Direct Payment | AR18: =SUM(AS18:BD18) -> 20000 | AU18: 5000 | AX18: 5000 | BA18: 5000 | BD18: 5000 | BE18: =SUM(BF18:BQ18) -> 20000 | BH18: 5000 | BK18: 5000 | BN18: 5000 | BQ18: 5000 | BR18: =SUM(BS18:BU18) -> 0 | BY18: =IF(ISBLANK(C18),0,1) -> 0 | BZ18: =IF(ISBLANK(D18),0,1) -> 0 | CA18: =IF(ISBLANK(F18),0,1) -> 0 | CB18: =IF(ISBLANK(G18),0,1) -> 0 | CC18: =IF(ISBLANK(N18),0,1) -> 1
C19: Pillar 5:Luntiang Paaralan Dagdag Kariktan | K19: =VLOOKUP(J19,links!B$2:C$24,2,FALSE) -> #N/A | BY19: =IF(ISBLANK(C19),0,1) -> 1 | BZ19: =IF(ISBLANK(D19),0,1) -> 0 | CA19: =IF(ISBLANK(F19),0,1) -> 0 | CB19: =IF(ISBLANK(G19),0,1) -> 0 | CC19: =IF(ISBLANK(N19),0,1) -> 0
D20: Implemented Luntiang Paaralan Dagdag Kariktan | E20: 2 | H20: No. of Luntiang Paaralan Dagdag Kariktan implemented | K20: =VLOOKUP(J20,links!B$2:C$24,2,FALSE) -> #N/A | X20: =SUM(Y20:AD20) -> 0 | AE20: =SUM(AF20:AQ20) -> 1 | AJ20: 1 | BY20: =IF(ISBLANK(C20),0,1) -> 0 | BZ20: =IF(ISBLANK(D20),0,1) -> 1 | CA20: =IF(ISBLANK(F20),0,1) -> 0 | CB20: =IF(ISBLANK(G20),0,1) -> 0 | CC20: =IF(ISBLANK(N20),0,1) -> 0
G21: Conduct school clean and green activity | H21: No. of school clean and green activity conducted | K21: =VLOOKUP(J21,links!B$2:C$24,2,FALSE) -> #N/A | R21: =R22 -> 25000 | X21: =SUM(Y21:AD21) -> 0 | AE21: =SUM(AF21:AQ21) -> 1 | AJ21: 1 | AR21: =AR22 -> 25000 | AS21: =AS22 -> 0 | AT21: =AT22 -> 0 | AU21: =AU22 -> 0 | AV21: =AV22 -> 0 | AW21: =AW22 -> 25000 | AX21: =AX22 -> 0 | AY21: =AY22 -> 0 | ... BQ21: =BQ22 -> 0 | BY21: =IF(ISBLANK(C21),0,1) -> 0 | BZ21: =IF(ISBLANK(D21),0,1) -> 0 | CA21: =IF(ISBLANK(F21),0,1) -> 0 | CB21: =IF(ISBLANK(G21),0,1) -> 1 | CC21: =IF(ISBLANK(N21),0,1) -> 0
I22: MOOE | J22: Supplies and Materials Expenses | K22: =VLOOKUP(J22,[1]links!B$2:C$24,2,FALSE) -> Supplies_and_Materials_Expenses | L22: Other Supplies and Materials Expenses | M22: =VLOOKUP(L22,[1]links!K$2:L$222,2,FALSE) -> 75 | N22: supplies for BUG | O22: 1 | P22: 25000 | Q22: 1 | R22: =O22*P22*Q22 -> 25000 | T22: N | U22: Y | V22: N | W22: Direct Payment | AR22: =SUM(AS22:BD22) -> 25000 | AW22: 25000 | BE22: =SUM(BF22:BQ22) -> 25000 | BJ22: 25000 | BR22: =SUM(BS22:BU22) -> 0 | BY22: =IF(ISBLANK(C22),0,1) -> 0 | BZ22: =IF(ISBLANK(D22),0,1) -> 0 | CA22: =IF(ISBLANK(F22),0,1) -> 0 | CB22: =IF(ISBLANK(G22),0,1) -> 0 | CC22: =IF(ISBLANK(N22),0,1) -> 1
C23: Pillar 5:Luntiang Kapaligiran sa Paaralan at Pantahanan para sa disiplinang pangkalusugan | K23: =VLOOKUP(J23,links!B$2:C$24,2,FALSE) -> #N/A | BY23: =IF(ISBLANK(C23),0,1) -> 1 | BZ23: =IF(ISBLANK(D23),0,1) -> 0 | CA23: =IF(ISBLANK(F23),0,1) -> 0 | CB23: =IF(ISBLANK(G23),0,1) -> 0 | CC23: =IF(ISBLANK(N23),0,1) -> 0
D24: Implemented Luntiang Kapaligiran sa Paaralan at Pantahanan para sa disiplinang pangkalusugan | E24: 3 | H24: No. of Luntiang Kapaligiran sa Paaralan at Pantahanan para sa disiplinang pangkalusugan implemented | K24: =VLOOKUP(J24,links!B$2:C$24,2,FALSE) -> #N/A | X24: =SUM(Y24:AD24) -> 0 | AE24: =SUM(AF24:AQ24) -> 1 | AJ24: 1 | BY24: =IF(ISBLANK(C24),0,1) -> 0 | BZ24: =IF(ISBLANK(D24),0,1) -> 1 | CA24: =IF(ISBLANK(F24),0,1) -> 0 | CB24: =IF(ISBLANK(G24),0,1) -> 0 | CC24: =IF(ISBLANK(N24),0,1) -> 0
G25: Conduct procurement of various supplies and materials for Gulayan sa Paaralan | H25: No. of procurement of various supplies and materials for Gulayan sa Paaralan conducted | K25: =VLOOKUP(J25,links!B$2:C$24,2,FALSE) -> #N/A | R25: =R26 -> 25000 | X25: =SUM(Y25:AD25) -> 0 | AE25: =SUM(AF25:AQ25) -> 1 | AJ25: 1 | AR25: =AR26 -> 25000 | AS25: =AS26 -> 0 | AT25: =AT26 -> 0 | AU25: =AU26 -> 0 | AV25: =AV26 -> 0 | AW25: =AW26 -> 25000 | AX25: =AX26 -> 0 | AY25: =AY26 -> 0 | ... BQ25: =BQ26 -> 0 | BY25: =IF(ISBLANK(C25),0,1) -> 0 | BZ25: =IF(ISBLANK(D25),0,1) -> 0 | CA25: =IF(ISBLANK(F25),0,1) -> 0 | CB25: =IF(ISBLANK(G25),0,1) -> 1 | CC25: =IF(ISBLANK(N25),0,1) -> 0
I26: MOOE | J26: Supplies and Materials Expenses | K26: =VLOOKUP(J26,[1]links!B$2:C$24,2,FALSE) -> Supplies_and_Materials_Expenses | L26: Other Supplies and Materials Expenses | M26: =VLOOKUP(L26,[1]links!K$2:L$222,2,FALSE) -> 75 | N26: cleaning supplies and construction material | O26: 1 | P26: 25000 | Q26: 1 | R26: =O26*P26*Q26 -> 25000 | T26: N | U26: Y | V26: N | W26: Direct Payment | AR26: =SUM(AS26:BD26) -> 25000 | AW26: 25000 | BE26: =SUM(BF26:BQ26) -> 25000 | BJ26: 25000 | BR26: =SUM(BS26:BU26) -> 0 | BY26: =IF(ISBLANK(C26),0,1) -> 0 | BZ26: =IF(ISBLANK(D26),0,1) -> 0 | CA26: =IF(ISBLANK(F26),0,1) -> 0 | CB26: =IF(ISBLANK(G26),0,1) -> 0 | CC26: =IF(ISBLANK(N26),0,1) -> 1
C27: Pillar 4:Records Management Strand 2.1 | K27: =VLOOKUP(J27,links!B$2:C$24,2,FALSE) -> #N/A | BY27: =IF(ISBLANK(C27),0,1) -> 1 | BZ27: =IF(ISBLANK(D27),0,1) -> 0 | CA27: =IF(ISBLANK(F27),0,1) -> 0 | CB27: =IF(ISBLANK(G27),0,1) -> 0 | CC27: =IF(ISBLANK(N27),0,1) -> 0
D28: Distributed school identification card | E28: 4 | H28: No. of school identification card distributed | K28: =VLOOKUP(J28,links!B$2:C$24,2,FALSE) -> #N/A | X28: =SUM(Y28:AD28) -> 0 | AE28: =SUM(AF28:AQ28) -> 1 | AJ28: 1 | BY28: =IF(ISBLANK(C28),0,1) -> 0 | BZ28: =IF(ISBLANK(D28),0,1) -> 1 | CA28: =IF(ISBLANK(F28),0,1) -> 0 | CB28: =IF(ISBLANK(G28),0,1) -> 0 | CC28: =IF(ISBLANK(N28),0,1) -> 0
G29: Conduct procurement of supplies for school identification card for students | H29: No. of procurement of supplies for school identification card for students conducted | K29: =VLOOKUP(J29,links!B$2:C$24,2,FALSE) -> #N/A | R29: =R30 -> 3000 | X29: =SUM(Y29:AD29) -> 0 | AE29: =SUM(AF29:AQ29) -> 1 | AJ29: 1 | AR29: =AR30 -> 3000 | AS29: =AS30 -> 0 | AT29: =AT30 -> 0 | AU29: =AU30 -> 0 | AV29: =AV30 -> 0 | AW29: =AW30 -> 3000 | AX29: =AX30 -> 0 | AY29: =AY30 -> 0 | ... BQ29: =BQ30 -> 0 | BY29: =IF(ISBLANK(C29),0,1) -> 0 | BZ29: =IF(ISBLANK(D29),0,1) -> 0 | CA29: =IF(ISBLANK(F29),0,1) -> 0 | CB29: =IF(ISBLANK(G29),0,1) -> 1 | CC29: =IF(ISBLANK(N29),0,1) -> 0
I30: MOOE | J30: Supplies and Materials Expenses | K30: =VLOOKUP(J30,[1]links!B$2:C$24,2,FALSE) -> Supplies_and_Materials_Expenses | L30: Other Supplies and Materials Expenses | M30: =VLOOKUP(L30,[1]links!K$2:L$222,2,FALSE) -> 75 | N30: pvc card sheet | O30: 1 | P30: 3000 | Q30: 1 | R30: =O30*P30*Q30 -> 3000 | T30: N | U30: Y | V30: N | W30: Direct Payment | AR30: =SUM(AS30:BD30) -> 3000 | AW30: 3000 | BE30: =SUM(BF30:BQ30) -> 3000 | BJ30: 3000 | BR30: =SUM(BS30:BU30) -> 0 | BY30: =IF(ISBLANK(C30),0,1) -> 0 | BZ30: =IF(ISBLANK(D30),0,1) -> 0 | CA30: =IF(ISBLANK(F30),0,1) -> 0 | CB30: =IF(ISBLANK(G30),0,1) -> 0 | CC30: =IF(ISBLANK(N30),0,1) -> 1
C31: Pillar 5:SDRRMO TEA - (Tools and Equipment Acquisition Program) | K31: =VLOOKUP(J31,links!B$2:C$24,2,FALSE) -> #N/A | BY31: =IF(ISBLANK(C31),0,1) -> 1 | BZ31: =IF(ISBLANK(D31),0,1) -> 0 | CA31: =IF(ISBLANK(F31),0,1) -> 0 | CB31: =IF(ISBLANK(G31),0,1) -> 0 | CC31: =IF(ISBLANK(N31),0,1) -> 0
D32: Equipped School Disaster Risk and Reduction Management Program | E32: 5 | H32: No. of School Disaster Risk and Reduction Management Program equipped | K32: =VLOOKUP(J32,links!B$2:C$24,2,FALSE) -> #N/A | X32: =SUM(Y32:AD32) -> 0 | AE32: =SUM(AF32:AQ32) -> 1 | AJ32: 1 | BY32: =IF(ISBLANK(C32),0,1) -> 0 | BZ32: =IF(ISBLANK(D32),0,1) -> 1 | CA32: =IF(ISBLANK(F32),0,1) -> 0 | CB32: =IF(ISBLANK(G32),0,1) -> 0 | CC32: =IF(ISBLANK(N32),0,1) -> 0
G33: Procure chainsaw | H33: No. of chainsaw procured | K33: =VLOOKUP(J33,links!B$2:C$24,2,FALSE) -> #N/A | R33: =R34 -> 20000 | X33: =SUM(Y33:AD33) -> 0 | AE33: =SUM(AF33:AQ33) -> 1 | AJ33: 1 | AR33: =AR34 -> 20000 | AS33: =AS34 -> 0 | AT33: =AT34 -> 20000 | AU33: =AU34 -> 0 | AV33: =AV34 -> 0 | AW33: =AW34 -> 0 | AX33: =AX34 -> 0 | AY33: =AY34 -> 0 | ... BQ33: =BQ34 -> 0 | BY33: =IF(ISBLANK(C33),0,1) -> 0 | BZ33: =IF(ISBLANK(D33),0,1) -> 0 | CA33: =IF(ISBLANK(F33),0,1) -> 0 | CB33: =IF(ISBLANK(G33),0,1) -> 1 | CC33: =IF(ISBLANK(N33),0,1) -> 0
I34: MOOE | J34: Supplies and Materials Expenses | K34: =VLOOKUP(J34,[1]links!B$2:C$24,2,FALSE) -> Supplies_and_Materials_Expenses | L34: Disaster Response and Rescue Equipment | M34: =VLOOKUP(L34,[1]links!K$2:L$222,2,FALSE) -> 66 | N34: chainsaw | O34: 1 | P34: 20000 | Q34: 1 | R34: =O34*P34*Q34 -> 20000 | T34: N | U34: Y | V34: N | W34: Direct Payment | AR34: =SUM(AS34:BD34) -> 20000 | AT34: 20000 | BE34: =SUM(BF34:BQ34) -> 20000 | BG34: 20000 | BR34: =SUM(BS34:BU34) -> 0 | BY34: =IF(ISBLANK(C34),0,1) -> 0 | BZ34: =IF(ISBLANK(D34),0,1) -> 0 | CA34: =IF(ISBLANK(F34),0,1) -> 0 | CB34: =IF(ISBLANK(G34),0,1) -> 0 | CC34: =IF(ISBLANK(N34),0,1) -> 1
C35: Pillar1:PLACE - Provisin for Learners and Curriculum Enhancers | K35: =VLOOKUP(J35,links!B$2:C$24,2,FALSE) -> #N/A | BY35: =IF(ISBLANK(C35),0,1) -> 1 | BZ35: =IF(ISBLANK(D35),0,1) -> 0 | CA35: =IF(ISBLANK(F35),0,1) -> 0 | CB35: =IF(ISBLANK(G35),0,1) -> 0 | CC35: =IF(ISBLANK(N35),0,1) -> 0
D36: Provided classrooms with thermometer hygrometer | E36: 6 | H36: No. of classrooms with thermometer hygrometer provided | K36: =VLOOKUP(J36,links!B$2:C$24,2,FALSE) -> #N/A | X36: =SUM(Y36:AD36) -> 0 | AE36: =SUM(AF36:AQ36) -> 60 | AG36: 60 | BY36: =IF(ISBLANK(C36),0,1) -> 0 | BZ36: =IF(ISBLANK(D36),0,1) -> 1 | CA36: =IF(ISBLANK(F36),0,1) -> 0 | CB36: =IF(ISBLANK(G36),0,1) -> 0 | CC36: =IF(ISBLANK(N36),0,1) -> 0
G37: Procure thermometer hygrometer | H37: No. of thermometer hygrometer procured | K37: =VLOOKUP(J37,links!B$2:C$24,2,FALSE) -> #N/A | R37: =R38 -> 60000 | X37: =SUM(Y37:AD37) -> 0 | AE37: =SUM(AF37:AQ37) -> 60 | AG37: 60 | AR37: =AR38 -> 60000 | AS37: =AS38 -> 0 | AT37: =AT38 -> 60000 | AU37: =AU38 -> 0 | AV37: =AV38 -> 0 | AW37: =AW38 -> 0 | AX37: =AX38 -> 0 | AY37: =AY38 -> 0 | ... BQ37: =BQ38 -> 0 | BR37: =SUM(BR113:BR115) -> 0 | BS37: =SUM(BS113:BS115) -> 0 | BT37: =SUM(BT113:BT115) -> 0 | BU37: =SUM(BU113:BU115) -> 0 | BY37: =IF(ISBLANK(C37),0,1) -> 0 | BZ37: =IF(ISBLANK(D37),0,1) -> 0 | CA37: =IF(ISBLANK(F37),0,1) -> 0 | CB37: =IF(ISBLANK(G37),0,1) -> 1 | CC37: =IF(ISBLANK(N37),0,1) -> 0
I38: MOOE | J38: Supplies and Materials Expenses | K38: =VLOOKUP(J38,[1]links!B$2:C$24,2,FALSE) -> Supplies_and_Materials_Expenses | L38: Information and Communications Technology Equipment | M38: =VLOOKUP(L38,[1]links!K$2:L$222,2,FALSE) -> 62 | N38: thermometer hygrometer | O38: 60 | P38: 1000 | Q38: 1 | R38: =O38*P38*Q38 -> 60000 | T38: N | U38: Y | V38: N | W38: Direct Payment | AR38: =SUM(AS38:BD38) -> 60000 | AT38: 60000 | BE38: =SUM(BF38:BQ38) -> 60000 | BG38: 60000 | BR38: =SUM(BS38:BU38) -> 0 | BY38: =IF(ISBLANK(C38),0,1) -> 0 | BZ38: =IF(ISBLANK(D38),0,1) -> 0 | CA38: =IF(ISBLANK(F38),0,1) -> 0 | CB38: =IF(ISBLANK(G38),0,1) -> 0 | CC38: =IF(ISBLANK(N38),0,1) -> 1
C39: Pillar 1:Sports Enhancement Program | K39: =VLOOKUP(J39,links!B$2:C$24,2,FALSE) -> #N/A | BY39: =IF(ISBLANK(C39),0,1) -> 1 | BZ39: =IF(ISBLANK(D39),0,1) -> 0 | CA39: =IF(ISBLANK(F39),0,1) -> 0 | CB39: =IF(ISBLANK(G39),0,1) -> 0 | CC39: =IF(ISBLANK(N39),0,1) -> 0
D40: Equipped schools' individual, dual, and team sports | E40: 7 | H40: No. of schools' individual, dual, and team sports equipped | K40: =VLOOKUP(J40,links!B$2:C$24,2,FALSE) -> #N/A | X40: =SUM(Y40:AD40) -> 0 | AE40: =SUM(AF40:AQ40) -> 5 | AG40: 5 | BY40: =IF(ISBLANK(C40),0,1) -> 0 | BZ40: =IF(ISBLANK(D40),0,1) -> 1 | CA40: =IF(ISBLANK(F40),0,1) -> 0 | CB40: =IF(ISBLANK(G40),0,1) -> 0 | CC40: =IF(ISBLANK(N40),0,1) -> 0
G41: Conduct procurement of various sports equipment for Arnis, Badminton, 3x3 Baskketball, Futsal and Badminton | H41: No. of procurement of various sports equipment for Arnis, Badminton, 3x3 Baskketball, Futsal and Badminton conducted | K41: =VLOOKUP(J41,links!B$2:C$24,2,FALSE) -> #N/A | R41: =R42 -> 50000 | X41: =SUM(Y41:AD41) -> 0 | AE41: =SUM(AF41:AQ41) -> 1 | AG41: 1 | AR41: =AR42 -> 50000 | AS41: =AS42 -> 0 | AT41: =AT42 -> 50000 | AU41: =AU42 -> 0 | AV41: =AV42 -> 0 | AW41: =AW42 -> 0 | AX41: =AX42 -> 0 | AY41: =AY42 -> 0 | ... BQ41: =BQ42 -> 0 | BR41: =SUM(BR113:BR118) -> 3000 | BS41: =SUM(BS113:BS118) -> 0 | BT41: =SUM(BT113:BT118) -> 0 | BU41: =SUM(BU113:BU118) -> 0 | BY41: =IF(ISBLANK(C41),0,1) -> 0 | BZ41: =IF(ISBLANK(D41),0,1) -> 0 | CA41: =IF(ISBLANK(F41),0,1) -> 0 | CB41: =IF(ISBLANK(G41),0,1) -> 1 | CC41: =IF(ISBLANK(N41),0,1) -> 0
I42: MOOE | J42: Supplies and Materials Expenses | K42: =VLOOKUP(J42,[1]links!B$2:C$24,2,FALSE) -> Supplies_and_Materials_Expenses | L42: Sports Equipment | M42: =VLOOKUP(L42,[1]links!K$2:L$222,2,FALSE) -> 69 | N42: various sports equipment | O42: 1 | P42: 50000 | Q42: 1 | R42: =O42*P42*Q42 -> 50000 | T42: N | U42: Y | V42: N | W42: Direct Payment | AR42: =SUM(AS42:BD42) -> 50000 | AT42: 50000 | BE42: =SUM(BF42:BQ42) -> 50000 | BG42: 50000 | BR42: =SUM(BS42:BU42) -> 0 | BY42: =IF(ISBLANK(C42),0,1) -> 0 | BZ42: =IF(ISBLANK(D42),0,1) -> 0 | CA42: =IF(ISBLANK(F42),0,1) -> 0 | CB42: =IF(ISBLANK(G42),0,1) -> 0 | CC42: =IF(ISBLANK(N42),0,1) -> 1
D43: Equipped schools' special program for the arts | E43: 8 | H43: No. of schools' special program for the arts equipped | K43: =VLOOKUP(J43,links!B$2:C$24,2,FALSE) -> #N/A | X43: =SUM(Y43:AD43) -> 0 | AE43: =SUM(AF43:AQ43) -> 1 | AG43: 1 | BY43: =IF(ISBLANK(C43),0,1) -> 0 | BZ43: =IF(ISBLANK(D43),0,1) -> 1 | CA43: =IF(ISBLANK(F43),0,1) -> 0 | CB43: =IF(ISBLANK(G43),0,1) -> 0 | CC43: =IF(ISBLANK(N43),0,1) -> 0
...

Sheet links
A1: expense_class | B1: object_group | F1: id | G1: Expense_Class | H1: object_expenditure_uacs | I1: object_group | J1: object_code | K1: object_expenditure_desc | L1: id | M1: PS | N1: GASS | O1: For Downloading (Board and Lodging) | P1: Y
A2: CO | B2: Intangible Assets Outlay | C2: Intangible_Assets_Outlay | F2: 1 | G2: PS | H2: 5010101001 | I2: Salaries and Wages | J2: Salaries and Wages - Regular | K2: Salaries and Wages - Regular | L2: 1 | M2: MOOE | N2: STO | O2: For Downloading (Program Support Fund) | P2: N
A3: CO | B3: Property, Plant and Equipment Outlay | C3: Property__Plant_and_Equipment_Outlay | F3: 2 | G3: PS | H3: 5010102000 | I3: Salaries and Wages | J3: Salaries and Wages - Casual/Contractual | K3: Salaries and Wages - Casual/Contractual | L3: 2 | M3: CO | N3: Operation | O3: Direct Payment
A4: MOOE | B4: Awards/Rewards and Prizes | C4: Awards_Rewards_and_Prizes | F4: 3 | G4: PS | H4: 5010201001 | I4: Other Compensation | J4: Personal Economic Relief Allowance (PERA) | K4: PERA - Civilian | L4: 3 | O4: Cash Advance
A5: MOOE | B5: Communication Expenses | C5: Communication_Expenses | F5: 4 | G5: PS | H5: 5010202000 | I5: Other Compensation | J5: Representation Allowance (RA) | K5: Representation Allowance (RA) | L5: 4 | O5: Fund Transfer to Other Agency
A6: MOOE | B6: Confidential, Intelligence and Extraordinary Expenses | C6: Confidential__Intelligence_and_Extraordinary_Expenses | F6: 5 | G6: PS | H6: 5010203001 | I6: Other Compensation | J6: Transportation Allowance (TA) | K6: Transportation Allowance (TA) | L6: 5
A7: MOOE | B7: Demolition/Relocation and Desilting/Dredging Expenses | C7: Demolition_Relocation_and_Desilting_Dredging_Expenses | F7: 6 | G7: PS | H7: 5010204001 | I7: Other Compensation | J7: Clothing/Uniform Allowance | K7: Clothing/Uniform Allowance - Civilian | L7: 6
A8: MOOE | B8: Financial Assistance/Subsidy | C8: Financial_Assistance_Subsidy | F8: 7 | G8: PS | H8: 5010205003 | I8: Other Compensation | J8: Subsistence Allowance (SA) | K8: Subsistence Allowance - Magna Carta for Public Health Workers under R.A. 7305 | L8: 7
A9: MOOE | B9: General Services | C9: General_Services | F9: 8 | G9: PS | H9: 5010206004 | I9: Other Compensation | J9: Laundry Allowance ( LA ) | K9: Laundry Allowance - Magna Carta Benefits for Public Health Workers under R.A. 7305 | L9: 8
A10: MOOE | B10: Generation, Transmission and Distribution Expenses | C10: Generation__Transmission_and_Distribution_Expenses | F10: 9 | G10: PS | H10: 5010207001 | I10: Other Compensation | J10: Quarters Allowance ( QA ) | K10: Quarters Allowance - Civilian | L10: 9
A11: MOOE | B11: Labor and Wages | C11: Labor_and_Wages | F11: 10 | G11: PS | H11: 5010207004 | I11: Other Compensation | J11: Quarters Allowance ( QA ) | K11: Quarters Allowance - Magna Carta Benefits for Public Health Workers under R.A. 7305 | L11: 10
A12: MOOE | B12: Other Maintenance and Operating Expenses | C12: Other_Maintenance_and_Operating_Expenses | F12: 11 | G12: PS | H12: 5010208001 | I12: Other Compensation | J12: Productivity Incentive Allowance (PIA) | K12: Productivity Incentive Allowance - Civilian | L12: 11
A13: MOOE | B13: Professional Services | C13: Professional_Services | F13: 12 | G13: PS | H13: 5010210001 | I13: Other Compensation | J13: Honoraria | K13: Honoraria - Civilian | L13: 12
A14: MOOE | B14: Repairs and Maintenance | C14: Repairs_and_Maintenance | F14: 13 | G14: PS | H14: 5010211002 | I14: Other Compensation | J14: Hazard Pay ( HP ) | K14: Hazard Duty Pay - Civilian | L14: 13
A15: MOOE | B15: Supplies and Materials Expenses | C15: Supplies_and_Materials_Expenses | F15: 14 | G15: PS | H15: 5010211005 | I15: Other Compensation | J15: Hazard Pay ( HP ) | K15: HP - Magna Carta Benefits for Public Health Workers under R.A. 7305 | L15: 14
A16: MOOE | B16: Survey, Research, Exploration and Development Expenses | C16: Survey__Research__Exploration_and_Development_Expenses | F16: 15 | G16: PS | H16: 5010212001 | I16: Other Compensation | J16: Longevity Pay ( LP ) | K16: Longevity Pay - Civilian | L16: 15
A17: MOOE | B17: Taxes, Insurance Premiums and Other Fees | C17: Taxes__Insurance_Premiums_and_Other_Fees | F17: 16 | G17: PS | H17: 5010213001 | I17: Other Compensation | J17: Overtime and Night Pay | K17: Overtime Pay | L17: 16
... A24: PS | B24: Salaries and Wages | C24: Salaries_and_Wages | F24: 23 | G24: PS | H24: 5010299036 | I24: Other Compensation | J24: Other Bonuses and Allowances | K24: Mid-Year Bonus - Civilian | L24: 23
F25: 24 | G25: PS | H25: 5010299038 | I25: Other Compensation | J25: Other Bonuses and Allowances | K25: Anniversary Bonus - Civilian | L25: 24
F26: 25 | G26: PS | H26: 5010301000 | I26: Personnel Benefit Contributions | J26: Retirement and Life Insurance Premiums | K26: Retirement and Life Insurance Premiums | L26: 25
F27: 26 | G27: PS | H27: 5010302001 | I27: Personnel Benefit Contributions | J27: Pag-IBIG Contributions | K27: Pag-IBIG - Civilian | L27: 26
F28: 27 | G28: PS | H28: 5010303001 | I28: Personnel Benefit Contributions | J28: PhilHealth Contributions | K28: PhilHealth - Civilian | L28: 27
F29: 28 | G29: PS | H29: 5010304001 | I29: Personnel Benefit Contributions | J29: Employees Compensation Insurance Premiums (ECIP) | K29: ECIP - Civilian | L29: 28
F30: 29 | G30: PS | H30: 5010402001 | I30: Other Personnel Benefits | J30: Retirement Gratuity | K30: Retirement Gratuity - Civilian | L30: 29
F31: 30 | G31: PS | H31: 5010403001 | I31: Other Personnel Benefits | J31: Terminal Leave Benefits | K31: Terminal Leave Benefits - Civilian | L31: 30
F32: 31 | G32: PS | H32: 5010499001 | I32: Other Personnel Benefits | J32: Other Personnel Benefits | K32: Lump-sum for Creation of New Positions - Civilian | L32: 31
F33: 32 | G33: PS | H33: 5010499003 | I33: Other Personnel Benefits | J33: Other Personnel Benefits | K33: Lump-sum for Reclassification of Positions | L33: 32
F34: 33 | G34: PS | H34: 5010499004 | I34: Other Personnel Benefits | J34: Other Personnel Benefits | K34: Lump-sum for Equivalent-Record Form | L34: 33
F35: 34 | G35: PS | H35: 5010499005 | I35: Other Personnel Benefits | J35: Other Personnel Benefits | K35: Lump-sum for Master Teachers | L35: 34
F36: 35 | G36: PS | H36: 5010499006 | I36: Other Personnel Benefits | J36: Other Personnel Benefits | K36: Lump-sum for Compensation Adjustment | L36: 35
... F222: 221 | G222: CO | H222: 5060699000 | I222: Intangible Assets Outlay | J222: Other Intangible Assets | K222: Other Intangible Assets | L222: 221
